Workbook

Sheet Смета по ТСН-2001
A1: =Source!B1 -> Smeta.RU (495) 974-1589
K2: Форма № 1б
A3: Выполнение работ по установке архитектурных элементов из бетона при устройстве ограждений трибун, расположенных на территории «Парка Ремесел» достопримечательного места «ВСХВ-ВДНХ-ВВЦ» по адресу: 129223, г. Москва, проспект Мира, дом 119.
A4: (наименование стройки)
A6: =CONCATENATE( "ЛОКАЛЬНАЯ СМЕТА № ",IF(Source!F12<>"Новый объект", Source!F12, "")) -> ЛОКАЛЬНАЯ СМЕТА №
A7: (локальный сметный расчет)
A11: =IF(Source!G12<>"Новый объект", Source!G12, "") -> Крышки парапета
A12: (наименование работ и затрат, наименование объекта)
A14: =CONCATENATE( "Основание: чертежи № ", Source!J12) -> Основание: чертежи №
I15: базовая цена | J15: текущая цена
F16: Сметная стоимость | I16: =SUM(O1:O59)/1000 -> 403.40436 | J16: =(Source!F90/1000) -> 2278.1111 | K16: тыс.руб
F17: Строительные работы | I17: =SUM(X1:X59)/1000 -> 403.40436 | J17: =(Source!F79)/1000 -> 2278.1111 | K17: тыс.руб
F18: Монтажные работы | I18: =SUM(Y1:Y59)/1000 -> 0 | J18: =(Source!F80)/1000 -> 0 | K18: тыс.руб
F19: Оборудование | I19: =SUM(Z1:Z59)/1000 -> 0 | J19: =(Source!F71)/1000 -> 0 | K19: тыс.руб
F20: Прочие работы | I20: =SUM(AA1:AA59)/1000 -> 0 | J20: =(Source!F81+Source!F82)/1000 -> 0 | K20: тыс.руб
F21: Средства на оплату труда | I21: =SUM(W1:W59)/1000 -> 0.52598 | J21: =(Source!F77+ Source!F76)/1000 -> 12.90229 | K21: тыс.руб
F22: Кроме того:
F23: Возврат материалов | I23: =SUM(AE1:AE59)/1000 -> 0 | J23: =SUM(AF1:AF59)/1000 -> 0 | K23: тыс.руб
A24: Составлен(а) в уровне текущих (прогнозных) цен Коэффициенты к ТСН-2001 МГЭ №169 октябрь 2020 года
A25: №№ п/п | B25: Шифр расценки и коды ресурсов | C25: Наименование работ и затрат | D25: Единица измерения | E25: Кол-во единиц | F25: Цена на ед. изм. руб. | G25: Попра-вочные коэфф. | H25: Коэфф. зимних удоро-жаний | I25: ВСЕГО в базисном уровне цен, руб. | J25: Коэфф. пересчета и нормы НР и СП | K25: Всего в текущем уровне цен, руб.
A26: 1 | B26: 2 | C26: 3 | D26: 4 | E26: 5 | F26: 6 | G26: 7 | H26: 8 | I26: 9 | J26: 10 | K26: 11
A29: =Source!E24 -> 1 | B29: =Source!F24 -> 3.7-30-10 | C29: Установка плит парапета массой более 0,5 т | D29: =Source!H24 -> 100 сборных конструкций | E29: =Source!I24 -> 0.2 | Q29: =ROUND((Source!DN24/100)*ROUND((ROUND((Source!AF24*Source!AV24*Source!I24),2)),2), 2) -> 255.93 | R29: =Source!X24 -> 4895.95 | S29: =ROUND((Source!DO24/100)*ROUND((ROUND((Source!AF24*Source!AV24*Source!I24),2)),2), 2) -> 191.54 | T29: =Source!Y24 -> 2211.08 | U29: =ROUND((175/100)*ROUND((ROUND((Source!AE24*Source!AV24*Source!I24),2)),2), 2) -> 0 | V29: =ROUND((157/100)*ROUND(ROUND((ROUND((Source!AE24*Source!AV24*Source!I24),2)*Source!BS24),2), 2), 2) -> 0
C30: ="Объем: "&Source!I24&"=20/"&"100" -> Объем: 0,2=20/100
C31: ЗП | F31: =Source!AO24 -> 804.81 | G31: =Source!DG24 | H31: =Source!AV24 -> 1 | I31: =ROUND((ROUND((Source!AF24*Source!AV24*Source!I24),2)),2) -> 160.96 | J31: =IF(Source!BA24<> 0, Source!BA24, 1) -> 24.53 | K31: =Source!S24 -> 3948.35 | W31: =I31 -> 160.96
C32: ЭМ | F32: =Source!AM24 -> 116.64 | G32: =Source!DE24 | H32: =Source!AV24 -> 1 | I32: =(ROUND((ROUND(((Source!ET24)*Source!AV24*Source!I24),2)),2)+ROUND((ROUND(((Source!AE24-(Source!EU24))*Source!AV24*Source!I24),2)),2)) -> 23.33 | J32: =IF(Source!BB24<> 0, Source!BB24, 1) -> 10.81 | K32: =Source!Q24 -> 252.2
C33: МР | F33: =Source!AL24 -> 1069.39 | G33: =Source!DD24 | H33: =Source!AW24 -> 1 | I33: =ROUND((ROUND((Source!AC24*Source!AW24*Source!I24),2)),2) -> 213.88 | J33: =IF(Source!BC24<> 0, Source!BC24, 1) -> 8.22 | K33: =Source!P24 -> 1758.09
A34: =Source!E25 -> 1,1 | B34: =Source!F25 -> КП "ПромЖБИ" | C34: Плита парапетная 1110*3630мм Базисная стоимость: 7 948,03 = [53 220 / 1,2 / 5,58] | D34: =Source!H25 -> шт. | E34: =Source!I25 -> 12 | F34: =Source!AK25 -> 7948.03 | H34: =Source!AW25 -> 1 | I34: =ROUND((ROUND((Source!AC25*Source!AW25*Source!I25),2)),2)+(ROUND((ROUND(((Source!ET25)*Source!AV25*Source!I25),2)),2)+ROUND((ROUND(((Source!AE25-(Source!EU25))*Source!AV25*Source!I25),2)),2))+ROUND((ROUND((Source!AF25*Source!AV25*Source!I25),2)),2) -> 95376.36 | J34: =IF(Source!BC25<> 0, Source!BC25, 1) -> 5.58 | K34: =Source!O25 -> 532200.09 | Q34: =ROUND((Source!DN25/100)*ROUND((ROUND((Source!AF25*Source!AV25*Source!I25),2)),2), 2) -> 0 | R34: =Source!X25 -> 0 | S34: =ROUND((Source!DO25/100)*ROUND((ROUND((Source!AF25*Source!AV25*Source!I25),2)),2), 2) -> 0 | T34: =Source!Y25 -> 0 | U34: =ROUND((175/100)*ROUND((ROUND((Source!AE25*Source!AV25*Source!I25),2)),2), 2) -> 0 | V34: =ROUND((157/100)*ROUND(ROUND((ROUND((Source!AE25*Source!AV25*Source!I25),2)*Source!BS25),2), 2), 2) -> 0 | X34: =IF(Source!BI25<=1,I34, 0) -> 95376.36 | Y34: =IF(Source!BI25=2,I34, 0) -> 0 | Z34: =IF(Source!BI25=3,I34, 0) -> 0 | AA34: =IF(Source!BI25=4,I34, 0) -> 0
A35: =Source!E26 -> 1,2 | B35: =Source!F26 -> КП "ПромЖБИ" | C35: Плита парапетная 1030*3000мм Базисная стоимость: 6 285,84 = [42 090 / 1,2 / 5,58] | D35: =Source!H26 -> шт. | E35: =Source!I26 -> 8 | F35: =Source!AK26 -> 6285.84 | H35: =Source!AW26 -> 1 | I35: =ROUND((ROUND((Source!AC26*Source!AW26*Source!I26),2)),2)+(ROUND((ROUND(((Source!ET26)*Source!AV26*Source!I26),2)),2)+ROUND((ROUND(((Source!AE26-(Source!EU26))*Source!AV26*Source!I26),2)),2))+ROUND((ROUND((Source!AF26*Source!AV26*Source!I26),2)),2) -> 50286.72 | J35: =IF(Source!BC26<> 0, Source!BC26, 1) -> 5.58 | K35: =Source!O26 -> 280599.9 | Q35: =ROUND((Source!DN26/100)*ROUND((ROUND((Source!AF26*Source!AV26*Source!I26),2)),2), 2) -> 0 | R35: =Source!X26 -> 0 | S35: =ROUND((Source!DO26/100)*ROUND((ROUND((Source!AF26*Source!AV26*Source!I26),2)),2), 2) -> 0 | T35: =Source!Y26 -> 0 | U35: =ROUND((175/100)*ROUND((ROUND((Source!AE26*Source!AV26*Source!I26),2)),2), 2) -> 0 | V35: =ROUND((157/100)*ROUND(ROUND((ROUND((Source!AE26*Source!AV26*Source!I26),2)*Source!BS26),2), 2), 2) -> 0 | X35: =IF(Source!BI26<=1,I35, 0) -> 50286.72 | Y35: =IF(Source!BI26=2,I35, 0) -> 0 | Z35: =IF(Source!BI26=3,I35, 0) -> 0 | AA35: =IF(Source!BI26=4,I35, 0) -> 0
C36: НР от ЗП | D36: % | E36: =Source!DN24 -> 159 | I36: =SUM(Q29:Q35) -> 255.93 | J36: =Source!BZ24 -> 124 | K36: =SUM(R29:R35) -> 4895.95
C37: СП от ЗП | D37: % | E37: =Source!DO24 -> 119 | I37: =SUM(S29:S36) -> 191.54 | J37: =Source!CA24 -> 56 | K37: =SUM(T29:T36) -> 2211.08
C38: ЗТР | D38: чел-ч | E38: =Source!AQ24 -> 66.9 | G38: =Source!DI24 | H38: =Source!AV24 -> 1 | I38: =Source!U24 -> 13.38
H39: =I31+I32+I33+I36+I37+SUM(I34:I35) -> 146508.72 | J39: =K31+K32+K33+K36+K37+SUM(K34:K35) -> 825865.66 | O39: =I31+I32+I33+I36+I37+SUM(I34:I35) -> 146508.72 | P39: =K31+K32+K33+K36+K37+SUM(K34:K35) -> 825865.66 | X39: =IF(Source!BI24<=1,I31+I32+I33+I36+I37-0, 0) -> 845.64 | Y39: =IF(Source!BI24=2,I31+I32+I33+I36+I37-0, 0) -> 0 | Z39: =IF(Source!BI24=3,I31+I32+I33+I36+I37-0, 0) -> 0 | AA39: =IF(Source!BI24=4,I31+I32+I33+I36+I37,0) -> 0
A40: =Source!E27 -> 2 | B40: =Source!F27 -> 3.7-30-9 | C40: Установка плит парапета массой до 0,5 т | D40: =Source!H27 -> 100 сборных конструкций | E40: =Source!I27 -> 0.78 | Q40: =ROUND((Source!DN27/100)*ROUND((ROUND((Source!AF27*Source!AV27*Source!I27),2)),2), 2) -> 580.38 | R40: =Source!X27 -> 11102.89 | S40: =ROUND((Source!DO27/100)*ROUND((ROUND((Source!AF27*Source!AV27*Source!I27),2)),2), 2) -> 434.37 | T40: =Source!Y27 -> 5014.21 | U40: =ROUND((175/100)*ROUND((ROUND((Source!AE27*Source!AV27*Source!I27),2)),2), 2) -> 0 | V40: =ROUND((157/100)*ROUND(ROUND((ROUND((Source!AE27*Source!AV27*Source!I27),2)*Source!BS27),2), 2), 2) -> 0
C41: ="Объем: "&Source!I27&"=78/"&"100" -> Объем: 0,78=78/100
C42: ЗП | F42: =Source!AO27 -> 467.97 | G42: =Source!DG27 | H42: =Source!AV27 -> 1 | I42: =ROUND((ROUND((Source!AF27*Source!AV27*Source!I27),2)),2) -> 365.02 | J42: =IF(Source!BA27<> 0, Source!BA27, 1) -> 24.53 | K42: =Source!S27 -> 8953.94 | W42: =I42 -> 365.02
C43: ЭМ | F43: =Source!AM27 -> 57.83 | G43: =Source!DE27 | H43: =Source!AV27 -> 1 | I43: =(ROUND((ROUND(((Source!ET27)*Source!AV27*Source!I27),2)),2)+ROUND((ROUND(((Source!AE27-(Source!EU27))*Source!AV27*Source!I27),2)),2)) -> 45.11 | J43: =IF(Source!BB27<> 0, Source!BB27, 1) -> 10.81 | K43: =Source!Q27 -> 487.64
C44: МР | F44: =Source!AL27 -> 649.38 | G44: =Source!DD27 | H44: =Source!AW27 -> 1 | I44: =ROUND((ROUND((Source!AC27*Source!AW27*Source!I27),2)),2) -> 506.52 | J44: =IF(Source!BC27<> 0, Source!BC27, 1) -> 7.87 | K44: =Source!P27 -> 3986.31
A45: =Source!E28 -> 2,1 | B45: =Source!F28 -> КП "ПромЖБИ" | C45: Плита парапетная 540*2900мм Базисная стоимость: 3 500,60 = [23 440 / 1,2 / 5,58] | D45: =Source!H28 -> шт. | E45: =Source!I28 -> 36 | F45: =Source!AK28 -> 3500.6 | H45: =Source!AW28 -> 1 | I45: =ROUND((ROUND((Source!AC28*Source!AW28*Source!I28),2)),2)+(ROUND((ROUND(((Source!ET28)*Source!AV28*Source!I28),2)),2)+ROUND((ROUND(((Source!AE28-(Source!EU28))*Source!AV28*Source!I28),2)),2))+ROUND((ROUND((Source!AF28*Source!AV28*Source!I28),2)),2) -> 126021.6 | J45: =IF(Source!BC28<> 0, Source!BC28, 1) -> 5.58 | K45: =Source!O28 -> 703200.53 | Q45: =ROUND((Source!DN28/100)*ROUND((ROUND((Source!AF28*Source!AV28*Source!I28),2)),2), 2) -> 0 | R45: =Source!X28 -> 0 | S45: =ROUND((Source!DO28/100)*ROUND((ROUND((Source!AF28*Source!AV28*Source!I28),2)),2), 2) -> 0 | T45: =Source!Y28 -> 0 | U45: =ROUND((175/100)*ROUND((ROUND((Source!AE28*Source!AV28*Source!I28),2)),2), 2) -> 0 | V45: =ROUND((157/100)*ROUND(ROUND((ROUND((Source!AE28*Source!AV28*Source!I28),2)*Source!BS28),2), 2), 2) -> 0 | X45: =IF(Source!BI28<=1,I45, 0) -> 126021.6 | Y45: =IF(Source!BI28=2,I45, 0) -> 0 | Z45: =IF(Source!BI28=3,I45, 0) -> 0 | AA45: =IF(Source!BI28=4,I45, 0) -> 0
A46: =Source!E29 -> 2,2 | B46: =Source!F29 -> КП "ПромЖБИ" | C46: Плита парапетная 860*1760мм Базисная стоимость: 3 449,82 = [23 100 / 1,2 / 5,58] | D46: =Source!H29 -> шт. | E46: =Source!I29 -> 30 | F46: =Source!AK29 -> 3449.82 | H46: =Source!AW29 -> 1 | I46: =ROUND((ROUND((Source!AC29*Source!AW29*Source!I29),2)),2)+(ROUND((ROUND(((Source!ET29)*Source!AV29*Source!I29),2)),2)+ROUND((ROUND(((Source!AE29-(Source!EU29))*Source!AV29*Source!I29),2)),2))+ROUND((ROUND((Source!AF29*Source!AV29*Source!I29),2)),2) -> 103494.6 | J46: =IF(Source!BC29<> 0, Source!BC29, 1) -> 5.58 | K46: =Source!O29 -> 577499.87 | Q46: =ROUND((Source!DN29/100)*ROUND((ROUND((Source!AF29*Source!AV29*Source!I29),2)),2), 2) -> 0 | R46: =Source!X29 -> 0 | S46: =ROUND((Source!DO29/100)*ROUND((ROUND((Source!AF29*Source!AV29*Source!I29),2)),2), 2) -> 0 | T46: =Source!Y29 -> 0 | U46: =ROUND((175/100)*ROUND((ROUND((Source!AE29*Source!AV29*Source!I29),2)),2), 2) -> 0 | V46: =ROUND((157/100)*ROUND(ROUND((ROUND((Source!AE29*Source!AV29*Source!I29),2)*Source!BS29),2), 2), 2) -> 0 | X46: =IF(Source!BI29<=1,I46, 0) -> 103494.6 | Y46: =IF(Source!BI29=2,I46, 0) -> 0 | Z46: =IF(Source!BI29=3,I46, 0) -> 0 | AA46: =IF(Source!BI29=4,I46, 0) -> 0
A47: =Source!E30 -> 2,3 | B47: =Source!F30 -> КП "ПромЖБИ" | C47: Плита парапетная 860*920мм Базисная стоимость: 2 120,67 = [14 200 / 1,2 / 5,58] | D47: =Source!H30 -> шт. | E47: =Source!I30 -> 12 | F47: =Source!AK30 -> 2120.67 | H47: =Source!AW30 -> 1 | I47: =ROUND((ROUND((Source!AC30*Source!AW30*Source!I30),2)),2)+(ROUND((ROUND(((Source!ET30)*Source!AV30*Source!I30),2)),2)+ROUND((ROUND(((Source!AE30-(Source!EU30))*Source!AV30*Source!I30),2)),2))+ROUND((ROUND((Source!AF30*Source!AV30*Source!I30),2)),2) -> 25448.04 | J47: =IF(Source!BC30<> 0, Source!BC30, 1) -> 5.58 | K47: =Source!O30 -> 142000.06 | Q47: =ROUND((Source!DN30/100)*ROUND((ROUND((Source!AF30*Source!AV30*Source!I30),2)),2), 2) -> 0 | R47: =Source!X30 -> 0 | S47: =ROUND((Source!DO30/100)*ROUND((ROUND((Source!AF30*Source!AV30*Source!I30),2)),2), 2) -> 0 | T47: =Source!Y30 -> 0 | U47: =ROUND((175/100)*ROUND((ROUND((Source!AE30*Source!AV30*Source!I30),2)),2), 2) -> 0 | V47: =ROUND((157/100)*ROUND(ROUND((ROUND((Source!AE30*Source!AV30*Source!I30),2)*Source!BS30),2), 2), 2) -> 0 | X47: =IF(Source!BI30<=1,I47, 0) -> 25448.04 | Y47: =IF(Source!BI30=2,I47, 0) -> 0 | Z47: =IF(Source!BI30=3,I47, 0) -> 0 | AA47: =IF(Source!BI30=4,I47, 0) -> 0
...

Sheet Source
A1: 0 | B1: Smeta.RU (495) 974-1589 | D1: _PS_ | F1: 0 | G1: 0 | H1: 0 | I1: Smeta.RU | K1: 1 | L1: 63577 | M1: 10 | N1: 11 | O1: 0 | P1: 1 | Q1: 6
A12: 1 | B12: 95 | C12: 0 | D12: =ROW(A62) -> 62 | E12: 0 | F12: Новый объект | G12: Крышки парапета | I12: 0 | K12: 0 | O12: 0 | P12: 0 | Q12: 0 | R12: 157 | V12: 0 | BH12: Сметные нормы списания | BI12: Коды ОКП для ТСН-2001 МГЭ | BJ12: 1 | BK12: 1 | BL12: 0 | BM12: 0 | BN12: 1 | BO12: 0 | BP12: 6 | BQ12: 2 | BR12: 1 | BS12: 1 | BT12: 0 | BU12: 0 | BV12: 1 | BW12: 0 | BX12: 0 | BY12: ТСН-2001 (МГЭ) - Новое строительство | BZ12: Типовой расчет для ТСН-2001 МГЭ, Новая методика с выпуска доп. 43 (Строительство), Доп 58 | CA12: Территориальные сметные нормативы для Москвы ТСН-2001 (МГЭ) | CB12: Территориальные сметные нормативы для Москвы ТСН-2001 (МГЭ) | CC12: Территориальные сметные нормативы для Москвы ТСН-2001 (МГЭ) | CD12: Территориальные сметные нормативы для Москвы ТСН-2001 (МГЭ) | CE12: Поправки для ТСН-2001 от 21.10.2020 г. доп.58 | CF12: 0 | CG12: 0 | CH12: 18874376 | CK12: 58 | EC12: 0
A15: 15 | B15: 1
A18: 52 | B18: =B62 -> 95 | C18: =C62 -> 1 | D18: =D62 -> 12 | E18: =E62 -> 0 | F18: =F62 -> Новый объект | G18: =G62 -> Крышки парапета | O18: =O62 -> 2254887 | P18: =P62 -> 2241244.9 | Q18: =Q62 -> 739.84 | R18: =R62 -> 0 | S18: =S62 -> 12902.29 | T18: =T62 -> 0 | U18: =U62 -> 43.722 | V18: =V62 -> 0 | ... GX18: =GX62 -> 0
A20: 3 | B20: 1 | D20: =ROW(A32) -> 32 | F20: Новая локальная смета | G20: Новая локальная смета | I20: 0 | K20: 0 | V20: 0 | BX20: 0 | CF20: 0 | CG20: 0
A22: 52 | B22: =B32 -> 1 | C22: =C32 -> 3 | D22: =D32 -> 20 | E22: =E32 -> 0 | F22: =F32 -> Новая локальная смета | G22: =G32 -> Новая локальная смета | O22: =O32 -> 2254887 | P22: =P32 -> 2241244.9 | Q22: =Q32 -> 739.84 | R22: =R32 -> 0 | S22: =S32 -> 12902.29 | T22: =T32 -> 0 | U22: =U32 -> 43.722 | V22: =V32 -> 0 | ... GX22: =GX32 -> 0
A24: 17 | B24: 1 | C24: =ROW(SmtRes!A6) -> 6 | D24: =ROW(EtalonRes!A5) -> 5 | E24: 1 | F24: 3.7-30-10 | G24: Установка плит парапета массой более 0,5 т | H24: 100 сборных конструкций | I24: =ROUND(20/100,9) -> 0.2 | J24: 0 | O24: =ROUND(CP24,2) -> 5958.64 | P24: =ROUND((ROUND((AC24*AW24*I24),2)*BC24),2) -> 1758.09 | Q24: =(ROUND((ROUND(((ET24)*AV24*I24),2)*BB24),2)+ROUND((ROUND(((AE24-(EU24))*AV24*I24),2)*BS24),2)) -> 252.2 | R24: =ROUND((ROUND((AE24*AV24*I24),2)*BS24),2) -> 0 | S24: =ROUND((ROUND((AF24*AV24*I24),2)*BA24),2) -> 3948.35 | T24: =ROUND(CU24*I24,2) -> 0 | U24: =CV24*I24 -> 13.38 | V24: =CW24*I24 -> 0 | W24: =ROUND(CX24*I24,2) -> 0 | X24: =ROUND(CY24,2) -> 4895.95 | Y24: =ROUND(CZ24,2) -> 2211.08 | AA24: 44887815 | AB24: =ROUND((AC24+AD24+AF24),6) -> 1990.84 | AC24: =ROUND((ES24),6) -> 1069.39 | AD24: =ROUND((((ET24)-(EU24))+AE24),6) -> 116.64 | AE24: =ROUND((EU24),6) -> 0 | AF24: =ROUND((EV24),6) -> 804.81 | AG24: =ROUND((AP24),6) -> 0 | AH24: =(EW24) -> 66.9 | AI24: =(EX24) -> 0 | AJ24: =(AS24) -> 0 | AK24: 1990.84 | AL24: 1069.39 | AM24: 116.64 | AN24: 0 | AO24: 804.81 | AP24: 0 | AQ24: 66.9 | AR24: 0 | AS24: 0 | AT24: 124 | AU24: 56 | AV24: 1 | AW24: 1 | AZ24: 1 | BA24: 24.53 | BB24: 10.81 | BC24: 8.22 | BH24: 0 | BI24: 1 | BJ24: ТСН-2001.3 Доп. 56, Сб. 7, т. 30, поз. 10 | BM24: 55 | BN24: 0 | BO24: 3.7-30-10 | BP24: 1 | BQ24: 30 | BR24: 0 | BS24: 24.53 | BT24: 1 | BU24: 1 | BV24: 1 | BW24: 1 | BX24: 1 | BZ24: 124 | CA24: 56 | CE24: 30 | CF24: 0 | CG24: 0 | CM24: 0 | CO24: 0 | CP24: =(P24+Q24+S24) -> 5958.64 | CQ24: =ROUND((ROUND((AC24*AW24*1),2)*BC24),2) -> 8790.39 | CR24: =(ROUND((ROUND(((ET24)*AV24*1),2)*BB24),2)+ROUND((ROUND(((AE24-(EU24))*AV24*1),2)*BS24),2)) -> 1260.88 | CS24: =ROUND((ROUND((AE24*AV24*1),2)*BS24),2) -> 0 | CT24: =ROUND((ROUND((AF24*AV24*1),2)*BA24),2) -> 19741.99 | CU24: =AG24 -> 0 | CV24: =(AH24*AV24) -> 66.9 | CW24: =AI24 -> 0 | CX24: =AJ24 -> 0 | CY24: =S24*(BZ24/100) -> 4895.954 | CZ24: =S24*(CA24/100) -> 2211.076 | DN24: 159 | DO24: 119 | DP24: 1 | DQ24: 1 | DU24: 30517203 | DV24: 100 сборных конструкций | DW24: 100 сборных конструкций | DX24: 1 | EE24: 44388191 | EF24: 30 | EG24: Строительные работы | EH24: 0 | EJ24: 1 | EK24: 55 | EL24: ТСН-2001.3-7. 7-1...7-30, 7-31-1...7-31-6 | EM24: ТСН-2001.3-7-1 | EQ24: 0 | ER24: 1990.84 | ES24: 1069.39 | ET24: 116.64 | EU24: 0 | EV24: 804.81 | EW24: 66.9 | EX24: 0 | EY24: 0 | FQ24: 0 | FR24: =ROUND(IF(AND(BH24=3,BI24=3),P24,0),2) -> 0 | FS24: 0 | FX24: 159 | FY24: 119 | GD24: 0 | GF24: -707522438 | GG24: 2 | GH24: 1 | GI24: 2 | GJ24: 0 | GK24: =ROUND(R24*(R12)/100,2) -> 0 | GL24: =ROUND(IF(AND(BH24=3,BI24=3,FS24<>0),P24,0),2) -> 0 | GM24: =ROUND(O24+X24+Y24+GK24,2)+GX24 -> 13065.67 | GN24: =IF(OR(BI24=0,BI24=1),ROUND(O24+X24+Y24+GK24,2),0) -> 13065.67 | GO24: =IF(BI24=2,ROUND(O24+X24+Y24+GK24,2),0) -> 0 | GP24: =IF(BI24=4,ROUND(O24+X24+Y24+GK24,2)+GX24,0) -> 0 | GR24: 0 | GS24: 3 | GT24: 0 | GV24: =ROUND((GT24),6) -> 0 | GW24: 1 | GX24: =ROUND(HC24*I24,2) -> 0 | HA24: 0 | HB24: 0 | HC24: =GV24*GW24 -> 0 | IK24: 0
A25: 18 | B25: 1 | C25: 5 | E25: 1,1 | F25: КП "ПромЖБИ" | G25: Плита парапетная 1110*3630мм | H25: шт. | I25: =I24*J25 -> 12 | J25: 60 | O25: =ROUND(CP25,2) -> 532200.09 | P25: =ROUND((ROUND((AC25*AW25*I25),2)*BC25),2) -> 532200.09 | Q25: =(ROUND((ROUND(((ET25)*AV25*I25),2)*BB25),2)+ROUND((ROUND(((AE25-(EU25))*AV25*I25),2)*BS25),2)) -> 0 | R25: =ROUND((ROUND((AE25*AV25*I25),2)*BS25),2) -> 0 | S25: =ROUND((ROUND((AF25*AV25*I25),2)*BA25),2) -> 0 | T25: =ROUND(CU25*I25,2) -> 0 | U25: =CV25*I25 -> 0 | V25: =CW25*I25 -> 0 | W25: =ROUND(CX25*I25,2) -> 0 | X25: =ROUND(CY25,2) -> 0 | Y25: =ROUND(CZ25,2) -> 0 | AA25: 44887815 | AB25: =ROUND((AC25+AD25+AF25),6) -> 7948.03 | AC25: =ROUND((ES25),6) -> 7948.03 | AD25: =ROUND((((ET25)-(EU25))+AE25),6) -> 0 | AE25: =ROUND((EU25),6) -> 0 | AF25: =ROUND((EV25),6) -> 0 | AG25: =ROUND((AP25),6) -> 0 | AH25: =(EW25) -> 0 | AI25: =(EX25) -> 0 | AJ25: =(AS25) -> 0 | AK25: 7948.03 | AL25: 7948.03 | AM25: 0 | AN25: 0 | AO25: 0 | AP25: 0 | AQ25: 0 | AR25: 0 | AS25: 0 | AT25: 0 | AU25: 0 | AV25: 1 | AW25: 1 | AZ25: 1 | BA25: 1 | BB25: 1 | BC25: 5.58 | BH25: 3 | BI25: 1 | BM25: 55 | BN25: 0 | BP25: 0 | BQ25: 30 | BR25: 0 | BS25: 1 | BT25: 1 | BU25: 1 | BV25: 1 | BW25: 1 | BX25: 1 | BZ25: 0 | CA25: 0 | CE25: 30 | CF25: 0 | CG25: 0 | CM25: 0 | CO25: 0 | CP25: =(P25+Q25+S25) -> 532200.09 | CQ25: =ROUND((ROUND((AC25*AW25*1),2)*BC25),2) -> 44350.01 | CR25: =(ROUND((ROUND(((ET25)*AV25*1),2)*BB25),2)+ROUND((ROUND(((AE25-(EU25))*AV25*1),2)*BS25),2)) -> 0 | CS25: =ROUND((ROUND((AE25*AV25*1),2)*BS25),2) -> 0 | CT25: =ROUND((ROUND((AF25*AV25*1),2)*BA25),2) -> 0 | CU25: =AG25 -> 0 | CV25: =(AH25*AV25) -> 0 | CW25: =AI25 -> 0 | CX25: =AJ25 -> 0 | CY25: =S25*(BZ25/100) -> 0 | CZ25: =S25*(CA25/100) -> 0 | DN25: 159 | DO25: 119 | DP25: 1 | DQ25: 1 | DU25: 1010 | DV25: шт. | DW25: шт. | DX25: 1 | EE25: 44388191 | EF25: 30 | EG25: Строительные работы | EH25: 0 | EJ25: 1 | EK25: 55 | EL25: ТСН-2001.3-7. 7-1...7-30, 7-31-1...7-31-6 | EM25: ТСН-2001.3-7-1 | EQ25: 0 | ER25: 44350 | ES25: 7948.03 | ET25: 0 | EU25: 0 | EV25: 0 | EW25: 0 | EX25: 0 | EZ25: 5 | FC25: 1 | FD25: 18 | FF25: 53220 | FQ25: 0 | FR25: =ROUND(IF(AND(BH25=3,BI25=3),P25,0),2) -> 0 | FS25: 0 | FX25: 159 | FY25: 119 | GA25: [53 220 / 1,2 / 5,58] | GD25: 0 | GF25: 1342093602 | GG25: 2 | GH25: 3 | GI25: 3 | GJ25: 0 | GK25: =ROUND(R25*(R12)/100,2) -> 0 | GL25: =ROUND(IF(AND(BH25=3,BI25=3,FS25<>0),P25,0),2) -> 0 | GM25: =ROUND(O25+X25+Y25+GK25,2)+GX25 -> 532200.09 | GN25: =IF(OR(BI25=0,BI25=1),ROUND(O25+X25+Y25+GK25,2),0) -> 532200.09 | GO25: =IF(BI25=2,ROUND(O25+X25+Y25+GK25,2),0) -> 0 | GP25: =IF(BI25=4,ROUND(O25+X25+Y25+GK25,2)+GX25,0) -> 0 | GR25: 1 | GS25: 1 | GT25: 0 | GV25: =ROUND((GT25),6) -> 0 | GW25: 1 | GX25: =ROUND(HC25*I25,2) -> 0 | HA25: 0 | HB25: 0 | HC25: =GV25*GW25 -> 0 | IK25: 0
A26: 18 | B26: 1 | C26: 6 | E26: 1,2 | F26: КП "ПромЖБИ" | G26: Плита парапетная 1030*3000мм | H26: шт. | I26: =I24*J26 -> 8 | J26: 40 | O26: =ROUND(CP26,2) -> 280599.9 | P26: =ROUND((ROUND((AC26*AW26*I26),2)*BC26),2) -> 280599.9 | Q26: =(ROUND((ROUND(((ET26)*AV26*I26),2)*BB26),2)+ROUND((ROUND(((AE26-(EU26))*AV26*I26),2)*BS26),2)) -> 0 | R26: =ROUND((ROUND((AE26*AV26*I26),2)*BS26),2) -> 0 | S26: =ROUND((ROUND((AF26*AV26*I26),2)*BA26),2) -> 0 | T26: =ROUND(CU26*I26,2) -> 0 | U26: =CV26*I26 -> 0 | V26: =CW26*I26 -> 0 | W26: =ROUND(CX26*I26,2) -> 0 | X26: =ROUND(CY26,2) -> 0 | Y26: =ROUND(CZ26,2) -> 0 | AA26: 44887815 | AB26: =ROUND((AC26+AD26+AF26),6) -> 6285.84 | AC26: =ROUND((ES26),6) -> 6285.84 | AD26: =ROUND((((ET26)-(EU26))+AE26),6) -> 0 | AE26: =ROUND((EU26),6) -> 0 | AF26: =ROUND((EV26),6) -> 0 | AG26: =ROUND((AP26),6) -> 0 | AH26: =(EW26) -> 0 | AI26: =(EX26) -> 0 | AJ26: =(AS26) -> 0 | AK26: 6285.84 | AL26: 6285.84 | AM26: 0 | AN26: 0 | AO26: 0 | AP26: 0 | AQ26: 0 | AR26: 0 | AS26: 0 | AT26: 0 | AU26: 0 | AV26: 1 | AW26: 1 | AZ26: 1 | BA26: 1 | BB26: 1 | BC26: 5.58 | BH26: 3 | BI26: 1 | BM26: 55 | BN26: 0 | BP26: 0 | BQ26: 30 | BR26: 0 | BS26: 1 | BT26: 1 | BU26: 1 | BV26: 1 | BW26: 1 | BX26: 1 | BZ26: 0 | CA26: 0 | CE26: 30 | CF26: 0 | CG26: 0 | CM26: 0 | CO26: 0 | CP26: =(P26+Q26+S26) -> 280599.9 | CQ26: =ROUND((ROUND((AC26*AW26*1),2)*BC26),2) -> 35074.99 | CR26: =(ROUND((ROUND(((ET26)*AV26*1),2)*BB26),2)+ROUND((ROUND(((AE26-(EU26))*AV26*1),2)*BS26),2)) -> 0 | CS26: =ROUND((ROUND((AE26*AV26*1),2)*BS26),2) -> 0 | CT26: =ROUND((ROUND((AF26*AV26*1),2)*BA26),2) -> 0 | CU26: =AG26 -> 0 | CV26: =(AH26*AV26) -> 0 | CW26: =AI26 -> 0 | CX26: =AJ26 -> 0 | CY26: =S26*(BZ26/100) -> 0 | CZ26: =S26*(CA26/100) -> 0 | DN26: 159 | DO26: 119 | DP26: 1 | DQ26: 1 | DU26: 1010 | DV26: шт. | DW26: шт. | DX26: 1 | EE26: 44388191 | EF26: 30 | EG26: Строительные работы | EH26: 0 | EJ26: 1 | EK26: 55 | EL26: ТСН-2001.3-7. 7-1...7-30, 7-31-1...7-31-6 | EM26: ТСН-2001.3-7-1 | EQ26: 0 | ER26: 35075 | ES26: 6285.84 | ET26: 0 | EU26: 0 | EV26: 0 | EW26: 0 | EX26: 0 | EZ26: 5 | FC26: 1 | FD26: 18 | FF26: 42090 | FQ26: 0 | FR26: =ROUND(IF(AND(BH26=3,BI26=3),P26,0),2) -> 0 | FS26: 0 | FX26: 159 | FY26: 119 | GA26: [42 090 / 1,2 / 5,58] | GD26: 0 | GF26: -327971188 | GG26: 2 | GH26: 3 | GI26: 3 | GJ26: 0 | GK26: =ROUND(R26*(R12)/100,2) -> 0 | GL26: =ROUND(IF(AND(BH26=3,BI26=3,FS26<>0),P26,0),2) -> 0 | GM26: =ROUND(O26+X26+Y26+GK26,2)+GX26 -> 280599.9 | GN26: =IF(OR(BI26=0,BI26=1),ROUND(O26+X26+Y26+GK26,2),0) -> 280599.9 | GO26: =IF(BI26=2,ROUND(O26+X26+Y26+GK26,2),0) -> 0 | GP26: =IF(BI26=4,ROUND(O26+X26+Y26+GK26,2)+GX26,0) -> 0 | GR26: 1 | GS26: 1 | GT26: 0 | GV26: =ROUND((GT26),6) -> 0 | GW26: 1 | GX26: =ROUND(HC26*I26,2) -> 0 | HA26: 0 | HB26: 0 | HC26: =GV26*GW26 -> 0 | IK26: 0
A27: 17 | B27: 1 | C27: =ROW(SmtRes!A13) -> 13 | D27: =ROW(EtalonRes!A10) -> 10 | E27: 2 | F27: 3.7-30-9 | G27: Установка плит парапета массой до 0,5 т | H27: 100 сборных конструкций | I27: =ROUND(78/100,9) -> 0.78 | J27: 0 | O27: =ROUND(CP27,2) -> 13427.89 | P27: =ROUND((ROUND((AC27*AW27*I27),2)*BC27),2) -> 3986.31 | Q27: =(ROUND((ROUND(((ET27)*AV27*I27),2)*BB27),2)+ROUND((ROUND(((AE27-(EU27))*AV27*I27),2)*BS27),2)) -> 487.64 | R27: =ROUND((ROUND((AE27*AV27*I27),2)*BS27),2) -> 0 | S27: =ROUND((ROUND((AF27*AV27*I27),2)*BA27),2) -> 8953.94 | T27: =ROUND(CU27*I27,2) -> 0 | U27: =CV27*I27 -> 30.342 | V27: =CW27*I27 -> 0 | W27: =ROUND(CX27*I27,2) -> 0 | X27: =ROUND(CY27,2) -> 11102.89 | Y27: =ROUND(CZ27,2) -> 5014.21 | AA27: 44887815 | AB27: =ROUND((AC27+AD27+AF27),6) -> 1175.18 | AC27: =ROUND((ES27),6) -> 649.38 | AD27: =ROUND((((ET27)-(EU27))+AE27),6) -> 57.83 | AE27: =ROUND((EU27),6) -> 0 | AF27: =ROUND((EV27),6) -> 467.97 | AG27: =ROUND((AP27),6) -> 0 | AH27: =(EW27) -> 38.9 | AI27: =(EX27) -> 0 | AJ27: =(AS27) -> 0 | AK27: 1175.18 | AL27: 649.38 | AM27: 57.83 | AN27: 0 | AO27: 467.97 | AP27: 0 | AQ27: 38.9 | AR27: 0 | AS27: 0 | AT27: 124 | AU27: 56 | AV27: 1 | AW27: 1 | AZ27: 1 | BA27: 24.53 | BB27: 10.81 | BC27: 7.87 | BH27: 0 | BI27: 1 | BJ27: ТСН-2001.3 Доп. 56, Сб. 7, т. 30, поз. 9 | BM27: 55 | BN27: 0 | BO27: 3.7-30-9 | BP27: 1 | BQ27: 30 | BR27: 0 | BS27: 24.53 | BT27: 1 | BU27: 1 | BV27: 1 | BW27: 1 | BX27: 1 | BZ27: 124 | CA27: 56 | CE27: 30 | CF27: 0 | CG27: 0 | CM27: 0 | CO27: 0 | CP27: =(P27+Q27+S27) -> 13427.89 | CQ27: =ROUND((ROUND((AC27*AW27*1),2)*BC27),2) -> 5110.62 | CR27: =(ROUND((ROUND(((ET27)*AV27*1),2)*BB27),2)+ROUND((ROUND(((AE27-(EU27))*AV27*1),2)*BS27),2)) -> 625.14 | CS27: =ROUND((ROUND((AE27*AV27*1),2)*BS27),2) -> 0 | CT27: =ROUND((ROUND((AF27*AV27*1),2)*BA27),2) -> 11479.3 | CU27: =AG27 -> 0 | CV27: =(AH27*AV27) -> 38.9 | CW27: =AI27 -> 0 | CX27: =AJ27 -> 0 | CY27: =S27*(BZ27/100) -> 11102.886 | CZ27: =S27*(CA27/100) -> 5014.2064 | DN27: 159 | DO27: 119 | DP27: 1 | DQ27: 1 | DU27: 30517203 | DV27: 100 сборных конструкций | DW27: 100 сборных конструкций | DX27: 1 | EE27: 44388191 | EF27: 30 | EG27: Строительные работы | EH27: 0 | EJ27: 1 | EK27: 55 | EL27: ТСН-2001.3-7. 7-1...7-30, 7-31-1...7-31-6 | EM27: ТСН-2001.3-7-1 | EQ27: 0 | ER27: 1175.18 | ES27: 649.38 | ET27: 57.83 | EU27: 0 | EV27: 467.97 | EW27: 38.9 | EX27: 0 | EY27: 0 | FQ27: 0 | FR27: =ROUND(IF(AND(BH27=3,BI27=3),P27,0),2) -> 0 | FS27: 0 | FX27: 159 | FY27: 119 | GD27: 0 | GF27: 399836649 | GG27: 2 | GH27: 1 | GI27: 2 | GJ27: 0 | GK27: =ROUND(R27*(R12)/100,2) -> 0 | GL27: =ROUND(IF(AND(BH27=3,BI27=3,FS27<>0),P27,0),2) -> 0 | GM27: =ROUND(O27+X27+Y27+GK27,2)+GX27 -> 29544.99 | GN27: =IF(OR(BI27=0,BI27=1),ROUND(O27+X27+Y27+GK27,2),0) -> 29544.99 | GO27: =IF(BI27=2,ROUND(O27+X27+Y27+GK27,2),0) -> 0 | GP27: =IF(BI27=4,ROUND(O27+X27+Y27+GK27,2)+GX27,0) -> 0 | GR27: 0 | GS27: 3 | GT27: 0 | GV27: =ROUND((GT27),6) -> 0 | GW27: 1 | GX27: =ROUND(HC27*I27,2) -> 0 | HA27: 0 | HB27: 0 | HC27: =GV27*GW27 -> 0 | IK27: 0
A28: 18 | B28: 1 | C28: 13 | E28: 2,1 | F28: КП "ПромЖБИ" | G28: Плита парапетная 540*2900мм | H28: шт. | I28: =I27*J28 -> 36 | J28: 46.153846 | O28: =ROUND(CP28,2) -> 703200.53 | P28: =ROUND((ROUND((AC28*AW28*I28),2)*BC28),2) -> 703200.53 | Q28: =(ROUND((ROUND(((ET28)*AV28*I28),2)*BB28),2)+ROUND((ROUND(((AE28-(EU28))*AV28*I28),2)*BS28),2)) -> 0 | R28: =ROUND((ROUND((AE28*AV28*I28),2)*BS28),2) -> 0 | S28: =ROUND((ROUND((AF28*AV28*I28),2)*BA28),2) -> 0 | T28: =ROUND(CU28*I28,2) -> 0 | U28: =CV28*I28 -> 0 | V28: =CW28*I28 -> 0 | W28: =ROUND(CX28*I28,2) -> 0 | X28: =ROUND(CY28,2) -> 0 | Y28: =ROUND(CZ28,2) -> 0 | AA28: 44887815 | AB28: =ROUND((AC28+AD28+AF28),6) -> 3500.6 | AC28: =ROUND((ES28),6) -> 3500.6 | AD28: =ROUND((((ET28)-(EU28))+AE28),6) -> 0 | AE28: =ROUND((EU28),6) -> 0 | AF28: =ROUND((EV28),6) -> 0 | AG28: =ROUND((AP28),6) -> 0 | AH28: =(EW28) -> 0 | AI28: =(EX28) -> 0 | AJ28: =(AS28) -> 0 | AK28: 3500.6 | AL28: 3500.6 | AM28: 0 | AN28: 0 | AO28: 0 | AP28: 0 | AQ28: 0 | AR28: 0 | AS28: 0 | AT28: 0 | AU28: 0 | AV28: 1 | AW28: 1 | AZ28: 1 | BA28: 1 | BB28: 1 | BC28: 5.58 | BH28: 3 | BI28: 1 | BM28: 55 | BN28: 0 | BP28: 0 | BQ28: 30 | BR28: 0 | BS28: 1 | BT28: 1 | BU28: 1 | BV28: 1 | BW28: 1 | BX28: 1 | BZ28: 0 | CA28: 0 | CE28: 30 | CF28: 0 | CG28: 0 | CM28: 0 | CO28: 0 | CP28: =(P28+Q28+S28) -> 703200.53 | CQ28: =ROUND((ROUND((AC28*AW28*1),2)*BC28),2) -> 19533.35 | CR28: =(ROUND((ROUND(((ET28)*AV28*1),2)*BB28),2)+ROUND((ROUND(((AE28-(EU28))*AV28*1),2)*BS28),2)) -> 0 | CS28: =ROUND((ROUND((AE28*AV28*1),2)*BS28),2) -> 0 | CT28: =ROUND((ROUND((AF28*AV28*1),2)*BA28),2) -> 0 | CU28: =AG28 -> 0 | CV28: =(AH28*AV28) -> 0 | CW28: =AI28 -> 0 | CX28: =AJ28 -> 0 | CY28: =S28*(BZ28/100) -> 0 | CZ28: =S28*(CA28/100) -> 0 | DN28: 159 | DO28: 119 | DP28: 1 | DQ28: 1 | DU28: 1010 | DV28: шт. | DW28: шт. | DX28: 1 | EE28: 44388191 | EF28: 30 | EG28: Строительные работы | EH28: 0 | EJ28: 1 | EK28: 55 | EL28: ТСН-2001.3-7. 7-1...7-30, 7-31-1...7-31-6 | EM28: ТСН-2001.3-7-1 | EQ28: 0 | ER28: 19533.33 | ES28: 3500.6 | ET28: 0 | EU28: 0 | EV28: 0 | EW28: 0 | EX28: 0 | EZ28: 5 | FC28: 1 | FD28: 18 | FF28: 23440 | FQ28: 0 | FR28: =ROUND(IF(AND(BH28=3,BI28=3),P28,0),2) -> 0 | FS28: 0 | FX28: 159 | FY28: 119 | GA28: [23 440 / 1,2 / 5,58] | GD28: 0 | GF28: 1029990948 | GG28: 2 | GH28: 3 | GI28: 3 | GJ28: 0 | GK28: =ROUND(R28*(R12)/100,2) -> 0 | GL28: =ROUND(IF(AND(BH28=3,BI28=3,FS28<>0),P28,0),2) -> 0 | GM28: =ROUND(O28+X28+Y28+GK28,2)+GX28 -> 703200.53 | GN28: =IF(OR(BI28=0,BI28=1),ROUND(O28+X28+Y28+GK28,2),0) -> 703200.53 | GO28: =IF(BI28=2,ROUND(O28+X28+Y28+GK28,2),0) -> 0 | GP28: =IF(BI28=4,ROUND(O28+X28+Y28+GK28,2)+GX28,0) -> 0 | GR28: 1 | GS28: 1 | GT28: 0 | GV28: =ROUND((GT28),6) -> 0 | GW28: 1 | GX28: =ROUND(HC28*I28,2) -> 0 | HA28: 0 | HB28: 0 | HC28: =GV28*GW28 -> 0 | IK28: 0
A29: 18 | B29: 1 | C29: 11 | E29: 2,2 | F29: КП "ПромЖБИ" | G29: Плита парапетная 860*1760мм | H29: шт. | I29: =I27*J29 -> 30 | J29: 38.461538 | O29: =ROUND(CP29,2) -> 577499.87 | P29: =ROUND((ROUND((AC29*AW29*I29),2)*BC29),2) -> 577499.87 | Q29: =(ROUND((ROUND(((ET29)*AV29*I29),2)*BB29),2)+ROUND((ROUND(((AE29-(EU29))*AV29*I29),2)*BS29),2)) -> 0 | R29: =ROUND((ROUND((AE29*AV29*I29),2)*BS29),2) -> 0 | S29: =ROUND((ROUND((AF29*AV29*I29),2)*BA29),2) -> 0 | T29: =ROUND(CU29*I29,2) -> 0 | U29: =CV29*I29 -> 0 | V29: =CW29*I29 -> 0 | W29: =ROUND(CX29*I29,2) -> 0 | X29: =ROUND(CY29,2) -> 0 | Y29: =ROUND(CZ29,2) -> 0 | AA29: 44887815 | AB29: =ROUND((AC29+AD29+AF29),6) -> 3449.82 | AC29: =ROUND((ES29),6) -> 3449.82 | AD29: =ROUND((((ET29)-(EU29))+AE29),6) -> 0 | AE29: =ROUND((EU29),6) -> 0 | AF29: =ROUND((EV29),6) -> 0 | AG29: =ROUND((AP29),6) -> 0 | AH29: =(EW29) -> 0 | AI29: =(EX29) -> 0 | AJ29: =(AS29) -> 0 | AK29: 3449.82 | AL29: 3449.82 | AM29: 0 | AN29: 0 | AO29: 0 | AP29: 0 | AQ29: 0 | AR29: 0 | AS29: 0 | AT29: 0 | AU29: 0 | AV29: 1 | AW29: 1 | AZ29: 1 | BA29: 1 | BB29: 1 | BC29: 5.58 | BH29: 3 | BI29: 1 | BM29: 55 | BN29: 0 | BP29: 0 | BQ29: 30 | BR29: 0 | BS29: 1 | BT29: 1 | BU29: 1 | BV29: 1 | BW29: 1 | BX29: 1 | BZ29: 0 | CA29: 0 | CE29: 30 | CF29: 0 | CG29: 0 | CM29: 0 | CO29: 0 | CP29: =(P29+Q29+S29) -> 577499.87 | CQ29: =ROUND((ROUND((AC29*AW29*1),2)*BC29),2) -> 19250 | CR29: =(ROUND((ROUND(((ET29)*AV29*1),2)*BB29),2)+ROUND((ROUND(((AE29-(EU29))*AV29*1),2)*BS29),2)) -> 0 | CS29: =ROUND((ROUND((AE29*AV29*1),2)*BS29),2) -> 0 | CT29: =ROUND((ROUND((AF29*AV29*1),2)*BA29),2) -> 0 | CU29: =AG29 -> 0 | CV29: =(AH29*AV29) -> 0 | CW29: =AI29 -> 0 | CX29: =AJ29 -> 0 | CY29: =S29*(BZ29/100) -> 0 | CZ29: =S29*(CA29/100) -> 0 | DN29: 159 | DO29: 119 | DP29: 1 | DQ29: 1 | DU29: 1010 | DV29: шт. | DW29: шт. | DX29: 1 | EE29: 44388191 | EF29: 30 | EG29: Строительные работы | EH29: 0 | EJ29: 1 | EK29: 55 | EL29: ТСН-2001.3-7. 7-1...7-30, 7-31-1...7-31-6 | EM29: ТСН-2001.3-7-1 | EQ29: 0 | ER29: 19250 | ES29: 3449.82 | ET29: 0 | EU29: 0 | EV29: 0 | EW29: 0 | EX29: 0 | EZ29: 5 | FC29: 1 | FD29: 18 | FF29: 23100 | FQ29: 0 | FR29: =ROUND(IF(AND(BH29=3,BI29=3),P29,0),2) -> 0 | FS29: 0 | FX29: 159 | FY29: 119 | GA29: [23 100 / 1,2 / 5,58] | GD29: 0 | GF29: -213020699 | GG29: 2 | GH29: 3 | GI29: 3 | GJ29: 0 | GK29: =ROUND(R29*(R12)/100,2) -> 0 | GL29: =ROUND(IF(AND(BH29=3,BI29=3,FS29<>0),P29,0),2) -> 0 | GM29: =ROUND(O29+X29+Y29+GK29,2)+GX29 -> 577499.87 | GN29: =IF(OR(BI29=0,BI29=1),ROUND(O29+X29+Y29+GK29,2),0) -> 577499.87 | GO29: =IF(BI29=2,ROUND(O29+X29+Y29+GK29,2),0) -> 0 | GP29: =IF(BI29=4,ROUND(O29+X29+Y29+GK29,2)+GX29,0) -> 0 | GR29: 1 | GS29: 1 | GT29: 0 | GV29: =ROUND((GT29),6) -> 0 | GW29: 1 | GX29: =ROUND(HC29*I29,2) -> 0 | HA29: 0 | HB29: 0 | HC29: =GV29*GW29 -> 0 | IK29: 0
A30: 18 | B30: 1 | C30: 12 | E30: 2,3 | F30: КП "ПромЖБИ" | G30: Плита парапетная 860*920мм | H30: шт. | I30: =I27*J30 -> 12 | J30: 15.384615 | O30: =ROUND(CP30,2) -> 142000.06 | P30: =ROUND((ROUND((AC30*AW30*I30),2)*BC30),2) -> 142000.06 | Q30: =(ROUND((ROUND(((ET30)*AV30*I30),2)*BB30),2)+ROUND((ROUND(((AE30-(EU30))*AV30*I30),2)*BS30),2)) -> 0 | R30: =ROUND((ROUND((AE30*AV30*I30),2)*BS30),2) -> 0 | S30: =ROUND((ROUND((AF30*AV30*I30),2)*BA30),2) -> 0 | T30: =ROUND(CU30*I30,2) -> 0 | U30: =CV30*I30 -> 0 | V30: =CW30*I30 -> 0 | W30: =ROUND(CX30*I30,2) -> 0 | X30: =ROUND(CY30,2) -> 0 | Y30: =ROUND(CZ30,2) -> 0 | AA30: 44887815 | AB30: =ROUND((AC30+AD30+AF30),6) -> 2120.67 | AC30: =ROUND((ES30),6) -> 2120.67 | AD30: =ROUND((((ET30)-(EU30))+AE30),6) -> 0 | AE30: =ROUND((EU30),6) -> 0 | AF30: =ROUND((EV30),6) -> 0 | AG30: =ROUND((AP30),6) -> 0 | AH30: =(EW30) -> 0 | AI30: =(EX30) -> 0 | AJ30: =(AS30) -> 0 | AK30: 2120.67 | AL30: 2120.67 | AM30: 0 | AN30: 0 | AO30: 0 | AP30: 0 | AQ30: 0 | AR30: 0 | AS30: 0 | AT30: 0 | AU30: 0 | AV30: 1 | AW30: 1 | AZ30: 1 | BA30: 1 | BB30: 1 | BC30: 5.58 | BH30: 3 | BI30: 1 | BM30: 55 | BN30: 0 | BP30: 0 | BQ30: 30 | BR30: 0 | BS30: 1 | BT30: 1 | BU30: 1 | BV30: 1 | BW30: 1 | BX30: 1 | BZ30: 0 | CA30: 0 | CE30: 30 | CF30: 0 | CG30: 0 | CM30: 0 | CO30: 0 | CP30: =(P30+Q30+S30) -> 142000.06 | CQ30: =ROUND((ROUND((AC30*AW30*1),2)*BC30),2) -> 11833.34 | CR30: =(ROUND((ROUND(((ET30)*AV30*1),2)*BB30),2)+ROUND((ROUND(((AE30-(EU30))*AV30*1),2)*BS30),2)) -> 0 | CS30: =ROUND((ROUND((AE30*AV30*1),2)*BS30),2) -> 0 | CT30: =ROUND((ROUND((AF30*AV30*1),2)*BA30),2) -> 0 | CU30: =AG30 -> 0 | CV30: =(AH30*AV30) -> 0 | CW30: =AI30 -> 0 | CX30: =AJ30 -> 0 | CY30: =S30*(BZ30/100) -> 0 | CZ30: =S30*(CA30/100) -> 0 | DN30: 159 | DO30: 119 | DP30: 1 | DQ30: 1 | DU30: 1010 | DV30: шт. | DW30: шт. | DX30: 1 | EE30: 44388191 | EF30: 30 | EG30: Строительные работы | EH30: 0 | EJ30: 1 | EK30: 55 | EL30: ТСН-2001.3-7. 7-1...7-30, 7-31-1...7-31-6 | EM30: ТСН-2001.3-7-1 | EQ30: 0 | ER30: 11833.33 | ES30: 2120.67 | ET30: 0 | EU30: 0 | EV30: 0 | EW30: 0 | EX30: 0 | EZ30: 5 | FC30: 1 | FD30: 18 | FF30: 14200 | FQ30: 0 | FR30: =ROUND(IF(AND(BH30=3,BI30=3),P30,0),2) -> 0 | FS30: 0 | FX30: 159 | FY30: 119 | GA30: [14 200 / 1,2 / 5,58] | GD30: 0 | GF30: 1468371780 | GG30: 2 | GH30: 3 | GI30: 3 | GJ30: 0 | GK30: =ROUND(R30*(R12)/100,2) -> 0 | GL30: =ROUND(IF(AND(BH30=3,BI30=3,FS30<>0),P30,0),2) -> 0 | GM30: =ROUND(O30+X30+Y30+GK30,2)+GX30 -> 142000.06 | GN30: =IF(OR(BI30=0,BI30=1),ROUND(O30+X30+Y30+GK30,2),0) -> 142000.06 | GO30: =IF(BI30=2,ROUND(O30+X30+Y30+GK30,2),0) -> 0 | GP30: =IF(BI30=4,ROUND(O30+X30+Y30+GK30,2)+GX30,0) -> 0 | GR30: 1 | GS30: 1 | GT30: 0 | GV30: =ROUND((GT30),6) -> 0 | GW30: 1 | GX30: =ROUND(HC30*I30,2) -> 0 | HA30: 0 | HB30: 0 | HC30: =GV30*GW30 -> 0 | IK30: 0
A32: 51 | B32: =B20 -> 1 | C32: =A20 -> 3 | D32: =ROW(A20) -> 20 | F32: =IF(F20<>"",F20,"") -> Новая локальная смета | G32: =IF(G20<>"",G20,"") -> Новая локальная смета | H32: 0 | O32: =ROUND(AB32,2) -> 2254887 | P32: =ROUND(AC32,2) -> 2241244.9 | Q32: =ROUND(AD32,2) -> 739.84 | R32: =ROUND(AE32,2) -> 0 | S32: =ROUND(AF32,2) -> 12902.29 | T32: =ROUND(AG32,2) -> 0 | U32: =AH32 -> 43.722 | V32: =AI32 -> 0 | W32: =ROUND(AJ32,2) -> 0 | X32: =ROUND(AK32,2) -> 15998.84 | Y32: =ROUND(AL32,2) -> 7225.29 | AB32: =ROUND(SUMIF(AA24:AA30,"=44887815",O24:O30),2) -> 2254887 | AC32: =ROUND(SUMIF(AA24:AA30,"=44887815",P24:P30),2) -> 2241244.9 | AD32: =ROUND(SUMIF(AA24:AA30,"=44887815",Q24:Q30),2) -> 739.84 | AE32: =ROUND(SUMIF(AA24:AA30,"=44887815",R24:R30),2) -> 0 | AF32: =ROUND(SUMIF(AA24:AA30,"=44887815",S24:S30),2) -> 12902.29 | AG32: =ROUND(SUMIF(AA24:AA30,"=44887815",T24:T30),2) -> 0 | AH32: =SUMIF(AA24:AA30,"=44887815",U24:U30) -> 43.722 | AI32: =SUMIF(AA24:AA30,"=44887815",V24:V30) -> 0 | AJ32: =ROUND(SUMIF(AA24:AA30,"=44887815",W24:W30),2) -> 0 | AK32: =ROUND(SUMIF(AA24:AA30,"=44887815",X24:X30),2) -> 15998.84 | AL32: =ROUND(SUMIF(AA24:AA30,"=44887815",Y24:Y30),2) -> 7225.29 | AO32: =ROUND(BX32,2) -> 0 | AP32: =ROUND(BY32,2) -> 0 | AQ32: =ROUND(BZ32,2) -> 0 | AR32: =ROUND(CA32,2) -> 2278111.1 | AS32: =ROUND(CB32,2) -> 2278111.1 | AT32: =ROUND(CC32,2) -> 0 | AU32: =ROUND(CD32,2) -> 0 | AV32: =ROUND(CE32,2) -> 2241244.9 | ... BD32: =ROUND(CM32,2) -> 0 | BX32: =ROUND(SUMIF(AA24:AA30,"=44887815",FQ24:FQ30),2) -> 0 | BY32: =ROUND(SUMIF(AA24:AA30,"=44887815",FR24:FR30),2) -> 0 | BZ32: =ROUND(SUMIF(AA24:AA30,"=44887815",GL24:GL30),2) -> 0 | CA32: =ROUND(SUMIF(AA24:AA30,"=44887815",GM24:GM30),2) -> 2278111.1 | CB32: =ROUND(SUMIF(AA24:AA30,"=44887815",GN24:GN30),2) -> 2278111.1 | CC32: =ROUND(SUMIF(AA24:AA30,"=44887815",GO24:GO30),2) -> 0 | CD32: =ROUND(SUMIF(AA24:AA30,"=44887815",GP24:GP30),2) -> 0 | CE32: =AC32-BX32 -> 2241244.9 | CF32: =AC32-BY32 -> 2241244.9 | CG32: =BX32-BZ32 -> 0 | CH32: =AC32-BX32-BY32+BZ32 -> 2241244.9 | CI32: =BY32-BZ32 -> 0 | CJ32: =ROUND(SUMIF(AA24:AA30,"=44887815",GX24:GX30),2) -> 0 | CK32: =ROUND(SUMIF(AA24:AA30,"=44887815",GY24:GY30),2) -> 0 | CL32: =ROUND(SUMIF(AA24:AA30,"=44887815",GZ24:GZ30),2) -> 0 | CM32: =ROUND(SUMIF(AA24:AA30,"=44887815",HD24:HD30),2) -> 0 | GX32: 0
A34: 50 | B34: 0 | C34: 0 | D34: 1 | E34: 201 | F34: =ROUND(Source!O32,O34) -> 2254887 | G34: ПЗ | H34: Прямые затраты | K34: 201 | L34: 1 | M34: 3 | O34: 2
A35: 50 | B35: 0 | C35: 0 | D35: 1 | E35: 202 | F35: =ROUND(Source!P32,O35) -> 2241244.9 | G35: СтМатОб | H35: Стоимость материальных ресурсов (всего) | K35: 202 | L35: 2 | M35: 3 | O35: 2
A36: 50 | B36: 0 | C36: 0 | D36: 1 | E36: 222 | F36: =ROUND(Source!AO32,O36) -> 0 | G36: СтМатОбЗак | H36: Стоимость материалов и оборудования заказчика | K36: 222 | L36: 3 | M36: 3 | O36: 2
A37: 50 | B37: 0 | C37: 0 | D37: 1 | E37: 225 | F37: =ROUND(Source!AV32,O37) -> 2241244.9 | G37: СтМатОбПод | H37: Стоимость материалов и оборудования подрядчика | K37: 225 | L37: 4 | M37: 3 | O37: 2
A38: 50 | B38: 0 | C38: 0 | D38: 1 | E38: 226 | F38: =ROUND(Source!AW32,O38) -> 2241244.9 | G38: СтМат | H38: Стоимость материалов (всего) | K38: 226 | L38: 5 | M38: 3 | O38: 2
A39: 50 | B39: 0 | C39: 0 | D39: 1 | E39: 227 | F39: =ROUND(Source!AX32,O39) -> 0 | G39: СтМатЗак | H39: Стоимость материалов заказчика | K39: 227 | L39: 6 | M39: 3 | O39: 2
A40: 50 | B40: 0 | C40: 0 | D40: 1 | E40: 228 | F40: =ROUND(Source!AY32,O40) -> 2241244.9 | G40: СтМатПод | H40: Стоимость материалов подрядчика | K40: 228 | L40: 7 | M40: 3 | O40: 2
A41: 50 | B41: 0 | C41: 0 | D41: 1 | E41: 216 | F41: =ROUND(Source!AP32,O41) -> 0 | G41: Оборуд | H41: Стоимость оборудования (всего) | K41: 216 | L41: 8 | M41: 3 | O41: 2
A42: 50 | B42: 0 | C42: 0 | D42: 1 | E42: 223 | F42: =ROUND(Source!AQ32,O42) -> 0 | G42: ОборудЗак | H42: Стоимость оборудования заказчика | K42: 223 | L42: 9 | M42: 3 | O42: 2
A43: 50 | B43: 0 | C43: 0 | D43: 1 | E43: 229 | F43: =ROUND(Source!AZ32,O43) -> 0 | G43: ОборудПод | H43: Стоимость оборудования подрядчика | K43: 229 | L43: 10 | M43: 3 | O43: 2
A44: 50 | B44: 0 | C44: 0 | D44: 1 | E44: 203 | F44: =ROUND(Source!Q32,O44) -> 739.84 | G44: ЭММ | H44: Эксплуатация машин | K44: 203 | L44: 11 | M44: 3 | O44: 2
A45: 50 | B45: 0 | C45: 0 | D45: 1 | E45: 231 | F45: =ROUND(Source!BB32,O45) -> 0 | G45: ЭММсНРиСП | H45: Эксплуатация машин по ТСН-2001.16 | K45: 231 | L45: 12 | M45: 3 | O45: 2
A46: 50 | B46: 0 | C46: 0 | D46: 1 | E46: 204 | F46: =ROUND(Source!R32,O46) -> 0 | G46: ЗПМ | H46: ЗП машинистов | K46: 204 | L46: 13 | M46: 3 | O46: 2
A47: 50 | B47: 0 | C47: 0 | D47: 1 | E47: 205 | F47: =ROUND(Source!S32,O47) -> 12902.29 | G47: ОЗП | H47: Основная ЗП рабочих | K47: 205 | L47: 14 | M47: 3 | O47: 2
A48: 50 | B48: 0 | C48: 0 | D48: 1 | E48: 232 | F48: =ROUND(Source!BC32,O48) -> 0 | G48: ОЗПсНРиСП | H48: Основная ЗП рабочих по ТСН-2001.16 | K48: 232 | L48: 15 | M48: 3 | O48: 2
A49: 50 | B49: 0 | C49: 0 | D49: 1 | E49: 214 | F49: =ROUND(Source!AS32,O49) -> 2278111.1 | G49: Строит | H49: Строительные работы с НР и СП | K49: 214 | L49: 16 | M49: 3 | O49: 2
A50: 50 | B50: 0 | C50: 0 | D50: 1 | E50: 215 | F50: =ROUND(Source!AT32,O50) -> 0 | G50: Монтаж | H50: Монтажные работы с НР и СП | K50: 215 | L50: 17 | M50: 3 | O50: 2
A51: 50 | B51: 0 | C51: 0 | D51: 1 | E51: 217 | F51: =ROUND(Source!AU32,O51) -> 0 | G51: Прочие | H51: Прочие работы с НР и СП | K51: 217 | L51: 18 | M51: 3 | O51: 2
A52: 50 | B52: 0 | C52: 0 | D52: 1 | E52: 230 | F52: =ROUND(Source!BA32,O52) -> 0 | G52: ПрочиеЗатр | H52: Прочие затраты по ТСН-2001.16 | K52: 230 | L52: 19 | M52: 3 | O52: 2
A53: 50 | B53: 0 | C53: 0 | D53: 1 | E53: 206 | F53: =ROUND(Source!T32,O53) -> 0 | G53: ВозврМат | H53: Возврат материалов | K53: 206 | L53: 20 | M53: 3 | O53: 2
A54: 50 | B54: 0 | C54: 0 | D54: 1 | E54: 207 | F54: =Source!U32 -> 43.722 | G54: ТрудСтр | H54: Трудозатраты строителей | K54: 207 | L54: 21 | M54: 3 | O54: -1
A55: 50 | B55: 0 | C55: 0 | D55: 1 | E55: 208 | F55: =Source!V32 -> 0 | G55: ТрудМаш | H55: Трудозатраты машинистов | K55: 208 | L55: 22 | M55: 3 | O55: -1
A56: 50 | B56: 0 | C56: 0 | D56: 1 | E56: 209 | F56: =ROUND(Source!W32,O56) -> 0 | G56: ТранспМат | H56: Транспорт материалов | K56: 209 | L56: 23 | M56: 3 | O56: 2
A57: 50 | B57: 0 | C57: 0 | D57: 1 | E57: 233 | F57: =ROUND(Source!BD32,O57) -> 0 | G57: Перевозка | H57: Перевозка грузов | K57: 233 | L57: 24 | M57: 3 | O57: 2
A58: 50 | B58: 0 | C58: 0 | D58: 1 | E58: 210 | F58: =ROUND(Source!X32,O58) -> 15998.84 | G58: НР | H58: Накладные расходы | K58: 210 | L58: 25 | M58: 3 | O58: 2
A59: 50 | B59: 0 | C59: 0 | D59: 1 | E59: 211 | F59: =ROUND(Source!Y32,O59) -> 7225.29 | G59: СмПриб | H59: Сметная прибыль | K59: 211 | L59: 26 | M59: 3 | O59: 2
...

Sheet SourceObSm
A1: 0 | B1: Smeta.RU (495) 974-1589 | D1: _OBSM_ | F1: 0 | G1: 0 | H1: 0 | I1: Smeta.RU | K1: 1 | L1: 63577 | M1: 10 | N1: 11 | O1: 0 | P1: 1 | Q1: 6
A12: 1 | B12: 51 | C12: 0 | E12: 0 | F12: Новый объект | G12: Крышки парапета | I12: 0 | K12: 0 | O12: 0 | P12: 0 | Q12: 0 | R12: 157 | V12: 0 | BH12: Сметные нормы списания | BI12: Коды ОКП для ТСН-2001 МГЭ | BJ12: 1 | BK12: 1 | BL12: 0 | BM12: 0 | BN12: 1 | BO12: 0 | BP12: 6 | BQ12: 2 | BR12: 1 | BS12: 1 | BT12: 0 | BU12: 0 | BV12: 1 | BW12: 0 | BX12: 0 | BY12: ТСН-2001 (МГЭ) - Новое строительство | BZ12: Типовой расчет для ТСН-2001 МГЭ, Новая методика с выпуска доп. 43 (Строительство), Доп 58 | CA12: Территориальные сметные нормативы для Москвы ТСН-2001 (МГЭ) | CB12: Территориальные сметные нормативы для Москвы ТСН-2001 (МГЭ) | CC12: Территориальные сметные нормативы для Москвы ТСН-2001 (МГЭ) | CD12: Территориальные сметные нормативы для Москвы ТСН-2001 (МГЭ) | CE12: Поправки для ТСН-2001 от 21.10.2020 г. доп.58 | CF12: 0 | CG12: 0 | CH12: 18874376 | CK12: 58 | EC12: 0
A14: 22 | B14: 0 | C14: 0 | D14: 44887815 | E14: 0 | F14: 3
A16: 3 | B16: 1 | C16: Новая локальная смета | D16: Новая локальная смета | E16: =(Source!F49)/1000 -> 2278.1111 | F16: =(Source!F50)/1000 -> 0 | G16: =(Source!F41)/1000 -> 0 | H16: =(Source!F51)/1000+(Source!F52)/1000 -> 0 | I16: =E16+F16+G16+H16 -> 2278.1111 | J16: =(Source!F47)/1000 -> 12.90229 | AI16: 0 | AJ16: 0 | AN16: 0 | AT16: 2254887 | AU16: 2241244.9 | AV16: 0 | AW16: 0 | AX16: 0 | AY16: 739.84 | AZ16: 0 | BA16: 12902.29 | BB16: 2278111.1 | BC16: 0 | BD16: 0 | BE16: 0 | BF16: 43.722 | BG16: 0 | BH16: 0 | BI16: 15998.84 | BJ16: 7225.29 | BK16: 2278111.1
A18: 51 | E18: =SUMIF(A16:A17,3,E16:E17) -> 2278.1111 | F18: =SUMIF(A16:A17,3,F16:F17) -> 0 | G18: =SUMIF(A16:A17,3,G16:G17) -> 0 | H18: =SUMIF(A16:A17,3,H16:H17) -> 0 | I18: =SUMIF(A16:A17,3,I16:I17) -> 2278.1111 | J18: =SUMIF(A16:A17,3,J16:J17) -> 12.90229
A20: 50 | B20: 0 | C20: 0 | D20: 1 | E20: 201 | F20: 2254887 | G20: ПЗ | H20: Прямые затраты | K20: 201 | L20: 1 | M20: 3 | O20: 2
A21: 50 | B21: 0 | C21: 0 | D21: 1 | E21: 202 | F21: 2241244.9 | G21: СтМатОб | H21: Стоимость материальных ресурсов (всего) | K21: 202 | L21: 2 | M21: 3 | O21: 2
A22: 50 | B22: 0 | C22: 0 | D22: 1 | E22: 222 | F22: 0 | G22: СтМатОбЗак | H22: Стоимость материалов и оборудования заказчика | K22: 222 | L22: 3 | M22: 3 | O22: 2
A23: 50 | B23: 0 | C23: 0 | D23: 1 | E23: 225 | F23: 2241244.9 | G23: СтМатОбПод | H23: Стоимость материалов и оборудования подрядчика | K23: 225 | L23: 4 | M23: 3 | O23: 2
A24: 50 | B24: 0 | C24: 0 | D24: 1 | E24: 226 | F24: 2241244.9 | G24: СтМат | H24: Стоимость материалов (всего) | K24: 226 | L24: 5 | M24: 3 | O24: 2
A25: 50 | B25: 0 | C25: 0 | D25: 1 | E25: 227 | F25: 0 | G25: СтМатЗак | H25: Стоимость материалов заказчика | K25: 227 | L25: 6 | M25: 3 | O25: 2
A26: 50 | B26: 0 | C26: 0 | D26: 1 | E26: 228 | F26: 2241244.9 | G26: СтМатПод | H26: Стоимость материалов подрядчика | K26: 228 | L26: 7 | M26: 3 | O26: 2
A27: 50 | B27: 0 | C27: 0 | D27: 1 | E27: 216 | F27: 0 | G27: Оборуд | H27: Стоимость оборудования (всего) | K27: 216 | L27: 8 | M27: 3 | O27: 2
A28: 50 | B28: 0 | C28: 0 | D28: 1 | E28: 223 | F28: 0 | G28: ОборудЗак | H28: Стоимость оборудования заказчика | K28: 223 | L28: 9 | M28: 3 | O28: 2
A29: 50 | B29: 0 | C29: 0 | D29: 1 | E29: 229 | F29: 0 | G29: ОборудПод | H29: Стоимость оборудования подрядчика | K29: 229 | L29: 10 | M29: 3 | O29: 2
A30: 50 | B30: 0 | C30: 0 | D30: 1 | E30: 203 | F30: 739.84 | G30: ЭММ | H30: Эксплуатация машин | K30: 203 | L30: 11 | M30: 3 | O30: 2
A31: 50 | B31: 0 | C31: 0 | D31: 1 | E31: 231 | F31: 0 | G31: ЭММсНРиСП | H31: Эксплуатация машин по ТСН-2001.16 | K31: 231 | L31: 12 | M31: 3 | O31: 2
... A46: 50 | B46: 0 | C46: 0 | D46: 1 | E46: 224 | F46: 2278111.1 | G46: Всего | H46: Всего с НР и СП | K46: 224 | L46: 27 | M46: 3 | O46: 2
A48: -1
A51: 75 | B51: Уровень цен | C51: 2020 | D51: 0 | E51: 10 | G51: 0 | H51: 2 | I51: 1 | J51: 1 | K51: 93 | L51: 64 | M51: 0 | N51: 44887815 | O51: 1
A52: 1 | B52: Сборник индексов | C52: Коэффициенты к ТСН-2001 МГЭ | D52: 2020 | E52: 10 | F52: 1 | G52: 1 | H52: 0 | I52: 2 | J52: 1 | K52: 1 | L52: 1 | M52: 1 | N52: 1 | O52: 1 | P52: 1 | Q52: 1 | AA52: 169

Sheet SmtRes
A1: =ROW(Source!A24) -> 24 | B1: 44887815 | C1: 44887820 | D1: 30515951 | E1: 30515945 | F1: 1 | G1: 30515945 | H1: 1 | I1: 9999990008 | K1: Трудозатраты рабочих | L1: 1191 | N1: 1013 | O1: чел.-ч. | P1: чел.-ч. | Q1: 1 | W1: 0 | X1: 476480486 | Y1: 66.9 | AA1: 0 | AB1: 0 | AC1: 0 | AD1: 0 | AE1: 0 | AF1: 0 | AG1: 0 | AH1: 0 | AI1: 1 | AJ1: 1 | AK1: 1 | AL1: 1 | AN1: 0 | AO1: 1 | AP1: 0 | AQ1: 0 | AR1: 0 | AT1: 66.9 | AV1: 1 | AW1: 2 | AX1: 44887827 | AY1: 1 | AZ1: 0 | BA1: 1 | BB1: 0 | BC1: 0 | BD1: 0 | BE1: 0 | BF1: 0 | BG1: 0 | BH1: 0 | BI1: 0 | BJ1: 0 | BK1: 0 | BL1: 0 | BM1: 0 | BN1: 0 | BO1: 0 | BP1: 0 | BQ1: 0 | BR1: 0 | BS1: 0 | BT1: 0 | BU1: 0 | BV1: 0 | BW1: 0 | CX1: =Y1*Source!I24 -> 13.38 | CY1: =AD1 -> 0 | CZ1: =AH1 -> 0 | DA1: =AL1 -> 1 | DB1: =ROUND(ROUND(AT1*CZ1,2),6) -> 0 | DC1: =ROUND(ROUND(AT1*AG1,2),6) -> 0
A2: =ROW(Source!A24) -> 24 | B2: 44887815 | C2: 44887820 | D2: 30595787 | E2: 1 | F2: 1 | G2: 30515945 | H2: 2 | I2: 2.1-13-10 | J2: ТСН-2001.2. Доп. 56. п.1-13-10 (135201) | K2: Инверторы для ручной дуговой сварки, сварочный ток до 400 А | L2: 1367 | N2: 1011 | O2: маш.-ч. | P2: маш.-ч. | Q2: 1 | W2: 0 | X2: 1295654915 | Y2: 24 | AA2: 0 | AB2: 57.11 | AC2: 0 | AD2: 0 | AE2: 0 | AF2: 4.86 | AG2: 0 | AH2: 0 | AI2: 1 | AJ2: 10.81 | AK2: 24.53 | AL2: 1 | AN2: 0 | AO2: 1 | AP2: 0 | AQ2: 0 | AR2: 0 | AT2: 24 | AV2: 0 | AW2: 2 | AX2: 44887828 | AY2: 1 | AZ2: 0 | BA2: 2 | BB2: 0 | BC2: 0 | BD2: 0 | BE2: 0 | BF2: 0 | BG2: 0 | BH2: 0 | BI2: 0 | BJ2: 0 | BK2: 0 | BL2: 0 | BM2: 0 | BN2: 0 | BO2: 0 | BP2: 0 | BQ2: 0 | BR2: 0 | BS2: 0 | BT2: 0 | BU2: 0 | BV2: 0 | BW2: 0 | CX2: =Y2*Source!I24 -> 4.8 | CY2: =AB2 -> 57.11 | CZ2: =AF2 -> 4.86 | DA2: =AJ2 -> 10.81 | DB2: =ROUND(ROUND(AT2*CZ2,2),6) -> 116.64 | DC2: =ROUND(ROUND(AT2*AG2,2),6) -> 0
A3: =ROW(Source!A24) -> 24 | B3: 44887815 | C3: 44887820 | D3: 30572493 | E3: 1 | F3: 1 | G3: 30515945 | H3: 3 | I3: 1.1-1-1566 | J3: ТСН-2001.1. Доп. 1-42. Р. 1, о. 1, поз. 1566 | K3: Электроды, тип Э-42, 46, 50, диаметр 4 - 6 мм | L3: 1348 | N3: 1009 | O3: т | P3: т | Q3: 1000 | W3: 0 | X3: 1310716689 | Y3: 0.027 | AA3: 88075.44 | AB3: 0 | AC3: 0 | AD3: 0 | AE3: 7191.81 | AF3: 0 | AG3: 0 | AH3: 0 | AI3: 12.21 | AJ3: 1 | AK3: 1 | AL3: 1 | AN3: 0 | AO3: 1 | AP3: 0 | AQ3: 0 | AR3: 0 | AT3: 0.027 | AV3: 0 | AW3: 2 | AX3: 44887829 | AY3: 1 | AZ3: 0 | BA3: 3 | BB3: 0 | BC3: 0 | BD3: 0 | BE3: 0 | BF3: 0 | BG3: 0 | BH3: 0 | BI3: 0 | BJ3: 0 | BK3: 0 | BL3: 0 | BM3: 0 | BN3: 0 | BO3: 0 | BP3: 0 | BQ3: 0 | BR3: 0 | BS3: 0 | BT3: 0 | BU3: 0 | BV3: 0 | BW3: 0 | CX3: =Y3*Source!I24 -> 0.0054 | CY3: =AA3 -> 88075.44 | CZ3: =AE3 -> 7191.81 | DA3: =AI3 -> 12.21 | DB3: =ROUND(ROUND(AT3*CZ3,2),6) -> 194.18 | DC3: =ROUND(ROUND(AT3*AG3,2),6) -> 0
A4: =ROW(Source!A24) -> 24 | B4: 44887815 | C4: 44887820 | D4: 30589691 | E4: 1 | F4: 1 | G4: 30515945 | H4: 3 | I4: 1.3-2-5 | J4: ТСН-2001.1. Доп. 1-42. Р. 3, о. 2, поз. 5 | K4: Растворы цементные, марка 100 | L4: 1339 | N4: 1007 | O4: м3 | P4: м3 | Q4: 1 | W4: 0 | X4: -718781615 | Y4: 1.94 | AA4: 3316.78 | AB4: 0 | AC4: 0 | AD4: 0 | AE4: 451.14 | AF4: 0 | AG4: 0 | AH4: 0 | AI4: 7.33 | AJ4: 1 | AK4: 1 | AL4: 1 | AN4: 0 | AO4: 1 | AP4: 0 | AQ4: 0 | AR4: 0 | AT4: 1.94 | AV4: 0 | AW4: 2 | AX4: 44887830 | AY4: 1 | AZ4: 0 | BA4: 4 | BB4: 0 | BC4: 0 | BD4: 0 | BE4: 0 | BF4: 0 | BG4: 0 | BH4: 0 | BI4: 0 | BJ4: 0 | BK4: 0 | BL4: 0 | BM4: 0 | BN4: 0 | BO4: 0 | BP4: 0 | BQ4: 0 | BR4: 0 | BS4: 0 | BT4: 0 | BU4: 0 | BV4: 0 | BW4: 0 | CX4: =Y4*Source!I24 -> 0.388 | CY4: =AA4 -> 3316.78 | CZ4: =AE4 -> 451.14 | DA4: =AI4 -> 7.33 | DB4: =ROUND(ROUND(AT4*CZ4,2),6) -> 875.21 | DC4: =ROUND(ROUND(AT4*AG4,2),6) -> 0
A5: =ROW(Source!A24) -> 24 | B5: 44887815 | C5: 44887820 | D5: 0 | E5: 0 | F5: 1 | G5: 30515945 | H5: 3 | I5: КП "ПромЖБИ" | K5: Плита парапетная 1110*3630мм | L5: 1354 | N5: 1010 | O5: шт. | P5: шт. | Q5: 1 | W5: 0 | X5: 1342093602 | Y5: 60 | AA5: 44483.06 | AB5: 0 | AC5: 0 | AD5: 0 | AE5: 7948.03 | AF5: 0 | AG5: 0 | AH5: 0 | AI5: 5.58 | AJ5: 1 | AK5: 1 | AL5: 1 | AN5: 0 | AO5: 0 | AP5: 0 | AQ5: 0 | AR5: 0 | AT5: 60 | AV5: 0 | AW5: 1 | AX5: -1 | AY5: 0 | AZ5: 0 | BB5: 0 | BC5: 0 | BD5: 0 | BE5: 0 | BF5: 0 | BG5: 0 | BH5: 0 | BI5: 0 | BJ5: 0 | BK5: 0 | BL5: 0 | BM5: 0 | BN5: 0 | BO5: 0 | BP5: 0 | BQ5: 0 | BR5: 0 | BS5: 0 | BT5: 0 | BU5: 0 | BV5: 0 | BW5: 0 | CX5: =Y5*Source!I24 -> 12 | CY5: =AA5 -> 44483.06 | CZ5: =AE5 -> 7948.03 | DA5: =AI5 -> 5.58 | DB5: =ROUND(ROUND(AT5*CZ5,2),6) -> 476881.8 | DC5: =ROUND(ROUND(AT5*AG5,2),6) -> 0
A6: =ROW(Source!A24) -> 24 | B6: 44887815 | C6: 44887820 | D6: 0 | E6: 30515945 | F6: 1 | G6: 30515945 | H6: 3 | I6: КП "ПромЖБИ" | K6: Плита парапетная 1030*3000мм | L6: 1354 | N6: 1010 | O6: шт. | P6: шт. | Q6: 1 | W6: 0 | X6: -327971188 | Y6: 40 | AA6: 35180.21 | AB6: 0 | AC6: 0 | AD6: 0 | AE6: 6285.84 | AF6: 0 | AG6: 0 | AH6: 0 | AI6: 5.58 | AJ6: 1 | AK6: 1 | AL6: 1 | AN6: 0 | AO6: 0 | AP6: 0 | AQ6: 0 | AR6: 0 | AT6: 40 | AV6: 0 | AW6: 1 | AX6: -1 | AY6: 0 | AZ6: 0 | BB6: 0 | BC6: 0 | BD6: 0 | BE6: 0 | BF6: 0 | BG6: 0 | BH6: 0 | BI6: 0 | BJ6: 0 | BK6: 0 | BL6: 0 | BM6: 0 | BN6: 0 | BO6: 0 | BP6: 0 | BQ6: 0 | BR6: 0 | BS6: 0 | BT6: 0 | BU6: 0 | BV6: 0 | BW6: 0 | CX6: =Y6*Source!I24 -> 8 | CY6: =AA6 -> 35180.21 | CZ6: =AE6 -> 6285.84 | DA6: =AI6 -> 5.58 | DB6: =ROUND(ROUND(AT6*CZ6,2),6) -> 251433.6 | DC6: =ROUND(ROUND(AT6*AG6,2),6) -> 0
A7: =ROW(Source!A27) -> 27 | B7: 44887815 | C7: 44887870 | D7: 30515951 | E7: 30515945 | F7: 1 | G7: 30515945 | H7: 1 | I7: 9999990008 | K7: Трудозатраты рабочих | L7: 1191 | N7: 1013 | O7: чел.-ч. | P7: чел.-ч. | Q7: 1 | W7: 0 | X7: 476480486 | Y7: 38.9 | AA7: 0 | AB7: 0 | AC7: 0 | AD7: 0 | AE7: 0 | AF7: 0 | AG7: 0 | AH7: 0 | AI7: 1 | AJ7: 1 | AK7: 1 | AL7: 1 | AN7: 0 | AO7: 1 | AP7: 0 | AQ7: 0 | AR7: 0 | AT7: 38.9 | AV7: 1 | AW7: 2 | AX7: 44887877 | AY7: 1 | AZ7: 0 | BA7: 6 | BB7: 0 | BC7: 0 | BD7: 0 | BE7: 0 | BF7: 0 | BG7: 0 | BH7: 0 | BI7: 0 | BJ7: 0 | BK7: 0 | BL7: 0 | BM7: 0 | BN7: 0 | BO7: 0 | BP7: 0 | BQ7: 0 | BR7: 0 | BS7: 0 | BT7: 0 | BU7: 0 | BV7: 0 | BW7: 0 | CX7: =Y7*Source!I27 -> 30.342 | CY7: =AD7 -> 0 | CZ7: =AH7 -> 0 | DA7: =AL7 -> 1 | DB7: =ROUND(ROUND(AT7*CZ7,2),6) -> 0 | DC7: =ROUND(ROUND(AT7*AG7,2),6) -> 0
A8: =ROW(Source!A27) -> 27 | B8: 44887815 | C8: 44887870 | D8: 30595787 | E8: 1 | F8: 1 | G8: 30515945 | H8: 2 | I8: 2.1-13-10 | J8: ТСН-2001.2. Доп. 56. п.1-13-10 (135201) | K8: Инверторы для ручной дуговой сварки, сварочный ток до 400 А | L8: 1367 | N8: 1011 | O8: маш.-ч. | P8: маш.-ч. | Q8: 1 | W8: 0 | X8: 1295654915 | Y8: 11.9 | AA8: 0 | AB8: 57.11 | AC8: 0 | AD8: 0 | AE8: 0 | AF8: 4.86 | AG8: 0 | AH8: 0 | AI8: 1 | AJ8: 10.81 | AK8: 24.53 | AL8: 1 | AN8: 0 | AO8: 1 | AP8: 0 | AQ8: 0 | AR8: 0 | AT8: 11.9 | AV8: 0 | AW8: 2 | AX8: 44887878 | AY8: 1 | AZ8: 0 | BA8: 7 | BB8: 0 | BC8: 0 | BD8: 0 | BE8: 0 | BF8: 0 | BG8: 0 | BH8: 0 | BI8: 0 | BJ8: 0 | BK8: 0 | BL8: 0 | BM8: 0 | BN8: 0 | BO8: 0 | BP8: 0 | BQ8: 0 | BR8: 0 | BS8: 0 | BT8: 0 | BU8: 0 | BV8: 0 | BW8: 0 | CX8: =Y8*Source!I27 -> 9.282 | CY8: =AB8 -> 57.11 | CZ8: =AF8 -> 4.86 | DA8: =AJ8 -> 10.81 | DB8: =ROUND(ROUND(AT8*CZ8,2),6) -> 57.83 | DC8: =ROUND(ROUND(AT8*AG8,2),6) -> 0
A9: =ROW(Source!A27) -> 27 | B9: 44887815 | C9: 44887870 | D9: 30572493 | E9: 1 | F9: 1 | G9: 30515945 | H9: 3 | I9: 1.1-1-1566 | J9: ТСН-2001.1. Доп. 1-42. Р. 1, о. 1, поз. 1566 | K9: Электроды, тип Э-42, 46, 50, диаметр 4 - 6 мм | L9: 1348 | N9: 1009 | O9: т | P9: т | Q9: 1000 | W9: 0 | X9: 1310716689 | Y9: 0.01 | AA9: 88075.44 | AB9: 0 | AC9: 0 | AD9: 0 | AE9: 7191.81 | AF9: 0 | AG9: 0 | AH9: 0 | AI9: 12.21 | AJ9: 1 | AK9: 1 | AL9: 1 | AN9: 0 | AO9: 1 | AP9: 0 | AQ9: 0 | AR9: 0 | AT9: 0.01 | AV9: 0 | AW9: 2 | AX9: 44887879 | AY9: 1 | AZ9: 0 | BA9: 8 | BB9: 0 | BC9: 0 | BD9: 0 | BE9: 0 | BF9: 0 | BG9: 0 | BH9: 0 | BI9: 0 | BJ9: 0 | BK9: 0 | BL9: 0 | BM9: 0 | BN9: 0 | BO9: 0 | BP9: 0 | BQ9: 0 | BR9: 0 | BS9: 0 | BT9: 0 | BU9: 0 | BV9: 0 | BW9: 0 | CX9: =Y9*Source!I27 -> 0.0078 | CY9: =AA9 -> 88075.44 | CZ9: =AE9 -> 7191.81 | DA9: =AI9 -> 12.21 | DB9: =ROUND(ROUND(AT9*CZ9,2),6) -> 71.92 | DC9: =ROUND(ROUND(AT9*AG9,2),6) -> 0
A10: =ROW(Source!A27) -> 27 | B10: 44887815 | C10: 44887870 | D10: 30589691 | E10: 1 | F10: 1 | G10: 30515945 | H10: 3 | I10: 1.3-2-5 | J10: ТСН-2001.1. Доп. 1-42. Р. 3, о. 2, поз. 5 | K10: Растворы цементные, марка 100 | L10: 1339 | N10: 1007 | O10: м3 | P10: м3 | Q10: 1 | W10: 0 | X10: -718781615 | Y10: 1.28 | AA10: 3316.78 | AB10: 0 | AC10: 0 | AD10: 0 | AE10: 451.14 | AF10: 0 | AG10: 0 | AH10: 0 | AI10: 7.33 | AJ10: 1 | AK10: 1 | AL10: 1 | AN10: 0 | AO10: 1 | AP10: 0 | AQ10: 0 | AR10: 0 | AT10: 1.28 | AV10: 0 | AW10: 2 | AX10: 44887880 | AY10: 1 | AZ10: 0 | BA10: 9 | BB10: 0 | BC10: 0 | BD10: 0 | BE10: 0 | BF10: 0 | BG10: 0 | BH10: 0 | BI10: 0 | BJ10: 0 | BK10: 0 | BL10: 0 | BM10: 0 | BN10: 0 | BO10: 0 | BP10: 0 | BQ10: 0 | BR10: 0 | BS10: 0 | BT10: 0 | BU10: 0 | BV10: 0 | BW10: 0 | CX10: =Y10*Source!I27 -> 0.9984 | CY10: =AA10 -> 3316.78 | CZ10: =AE10 -> 451.14 | DA10: =AI10 -> 7.33 | DB10: =ROUND(ROUND(AT10*CZ10,2),6) -> 577.46 | DC10: =ROUND(ROUND(AT10*AG10,2),6) -> 0
A11: =ROW(Source!A27) -> 27 | B11: 44887815 | C11: 44887870 | D11: 0 | E11: 30515945 | F11: 1 | G11: 30515945 | H11: 3 | I11: КП "ПромЖБИ" | K11: Плита парапетная 860*1760мм | L11: 1354 | N11: 1010 | O11: шт. | P11: шт. | Q11: 1 | W11: 0 | X11: -213020699 | Y11: 38.461538 | AA11: 19307.75 | AB11: 0 | AC11: 0 | AD11: 0 | AE11: 3449.82 | AF11: 0 | AG11: 0 | AH11: 0 | AI11: 5.58 | AJ11: 1 | AK11: 1 | AL11: 1 | AN11: 0 | AO11: 0 | AP11: 0 | AQ11: 0 | AR11: 0 | AT11: 38.461538 | AV11: 0 | AW11: 1 | AX11: -1 | AY11: 0 | AZ11: 0 | BB11: 0 | BC11: 0 | BD11: 0 | BE11: 0 | BF11: 0 | BG11: 0 | BH11: 0 | BI11: 0 | BJ11: 0 | BK11: 0 | BL11: 0 | BM11: 0 | BN11: 0 | BO11: 0 | BP11: 0 | BQ11: 0 | BR11: 0 | BS11: 0 | BT11: 0 | BU11: 0 | BV11: 0 | BW11: 0 | CX11: =Y11*Source!I27 -> 30 | CY11: =AA11 -> 19307.75 | CZ11: =AE11 -> 3449.82 | DA11: =AI11 -> 5.58 | DB11: =ROUND(ROUND(AT11*CZ11,2),6) -> 132685.38 | DC11: =ROUND(ROUND(AT11*AG11,2),6) -> 0
A12: =ROW(Source!A27) -> 27 | B12: 44887815 | C12: 44887870 | D12: 0 | E12: 30515945 | F12: 1 | G12: 30515945 | H12: 3 | I12: КП "ПромЖБИ" | K12: Плита парапетная 860*920мм | L12: 1354 | N12: 1010 | O12: шт. | P12: шт. | Q12: 1 | W12: 0 | X12: 1468371780 | Y12: 15.384615 | AA12: 11868.84 | AB12: 0 | AC12: 0 | AD12: 0 | AE12: 2120.67 | AF12: 0 | AG12: 0 | AH12: 0 | AI12: 5.58 | AJ12: 1 | AK12: 1 | AL12: 1 | AN12: 0 | AO12: 0 | AP12: 0 | AQ12: 0 | AR12: 0 | AT12: 15.384615 | AV12: 0 | AW12: 1 | AX12: -1 | AY12: 0 | AZ12: 0 | BB12: 0 | BC12: 0 | BD12: 0 | BE12: 0 | BF12: 0 | BG12: 0 | BH12: 0 | BI12: 0 | BJ12: 0 | BK12: 0 | BL12: 0 | BM12: 0 | BN12: 0 | BO12: 0 | BP12: 0 | BQ12: 0 | BR12: 0 | BS12: 0 | BT12: 0 | BU12: 0 | BV12: 0 | BW12: 0 | CX12: =Y12*Source!I27 -> 12 | CY12: =AA12 -> 11868.84 | CZ12: =AE12 -> 2120.67 | DA12: =AI12 -> 5.58 | DB12: =ROUND(ROUND(AT12*CZ12,2),6) -> 32625.69 | DC12: =ROUND(ROUND(AT12*AG12,2),6) -> 0
A13: =ROW(Source!A27) -> 27 | B13: 44887815 | C13: 44887870 | D13: 0 | E13: 30515945 | F13: 1 | G13: 30515945 | H13: 3 | I13: КП "ПромЖБИ" | K13: Плита парапетная 540*2900мм | L13: 1354 | N13: 1010 | O13: шт. | P13: шт. | Q13: 1 | W13: 0 | X13: 1029990948 | Y13: 46.153846 | AA13: 19591.95 | AB13: 0 | AC13: 0 | AD13: 0 | AE13: 3500.6 | AF13: 0 | AG13: 0 | AH13: 0 | AI13: 5.58 | AJ13: 1 | AK13: 1 | AL13: 1 | AN13: 0 | AO13: 0 | AP13: 0 | AQ13: 0 | AR13: 0 | AT13: 46.153846 | AV13: 0 | AW13: 1 | AX13: -1 | AY13: 0 | AZ13: 0 | BB13: 0 | BC13: 0 | BD13: 0 | BE13: 0 | BF13: 0 | BG13: 0 | BH13: 0 | BI13: 0 | BJ13: 0 | BK13: 0 | BL13: 0 | BM13: 0 | BN13: 0 | BO13: 0 | BP13: 0 | BQ13: 0 | BR13: 0 | BS13: 0 | BT13: 0 | BU13: 0 | BV13: 0 | BW13: 0 | CX13: =Y13*Source!I27 -> 36 | CY13: =AA13 -> 19591.95 | CZ13: =AE13 -> 3500.6 | DA13: =AI13 -> 5.58 | DB13: =ROUND(ROUND(AT13*CZ13,2),6) -> 161566.15 | DC13: =ROUND(ROUND(AT13*AG13,2),6) -> 0

Sheet EtalonRes
A1: =ROW(Source!A24) -> 24 | B1: 44887827 | C1: 44887820 | D1: 30515951 | E1: 30515945 | F1: 1 | G1: 30515945 | H1: 1 | I1: 9999990008 | K1: Трудозатраты рабочих | L1: 1191 | N1: 1013 | O1: чел.-ч. | P1: чел.-ч. | Q1: 1 | X1: 66.9 | Y1: 0 | Z1: 0 | AA1: 0 | AB1: 0 | AC1: 0 | AD1: 1 | AE1: 1 | AG1: 66.9 | AH1: 2 | AI1: 44887827 | AJ1: 1 | AK1: 0 | AL1: 0 | AM1: 0 | AN1: 0 | AO1: 0 | AP1: 0 | AQ1: 0 | AR1: 0
A2: =ROW(Source!A24) -> 24 | B2: 44887828 | C2: 44887820 | D2: 30595787 | E2: 1 | F2: 1 | G2: 30515945 | H2: 2 | I2: 2.1-13-10 | J2: ТСН-2001.2. Доп. 56. п.1-13-10 (135201) | K2: Инверторы для ручной дуговой сварки, сварочный ток до 400 А | L2: 1367 | N2: 1011 | O2: маш.-ч. | P2: маш.-ч. | Q2: 1 | X2: 24 | Y2: 0 | Z2: 4.86 | AA2: 0 | AB2: 0 | AC2: 0 | AD2: 1 | AE2: 0 | AG2: 24 | AH2: 2 | AI2: 44887828 | AJ2: 2 | AK2: 0 | AL2: 0 | AM2: 0 | AN2: 0 | AO2: 0 | AP2: 0 | AQ2: 0 | AR2: 0
A3: =ROW(Source!A24) -> 24 | B3: 44887829 | C3: 44887820 | D3: 30572493 | E3: 1 | F3: 1 | G3: 30515945 | H3: 3 | I3: 1.1-1-1566 | J3: ТСН-2001.1. Доп. 1-42. Р. 1, о. 1, поз. 1566 | K3: Электроды, тип Э-42, 46, 50, диаметр 4 - 6 мм | L3: 1348 | N3: 1009 | O3: т | P3: т | Q3: 1000 | X3: 0.027 | Y3: 7191.81 | Z3: 0 | AA3: 0 | AB3: 0 | AC3: 0 | AD3: 1 | AE3: 0 | AG3: 0.027 | AH3: 2 | AI3: 44887829 | AJ3: 3 | AK3: 0 | AL3: 0 | AM3: 0 | AN3: 0 | AO3: 0 | AP3: 0 | AQ3: 0 | AR3: 0
A4: =ROW(Source!A24) -> 24 | B4: 44887830 | C4: 44887820 | D4: 30589691 | E4: 1 | F4: 1 | G4: 30515945 | H4: 3 | I4: 1.3-2-5 | J4: ТСН-2001.1. Доп. 1-42. Р. 3, о. 2, поз. 5 | K4: Растворы цементные, марка 100 | L4: 1339 | N4: 1007 | O4: м3 | P4: м3 | Q4: 1 | X4: 1.94 | Y4: 451.14 | Z4: 0 | AA4: 0 | AB4: 0 | AC4: 0 | AD4: 1 | AE4: 0 | AG4: 1.94 | AH4: 2 | AI4: 44887830 | AJ4: 4 | AK4: 0 | AL4: 0 | AM4: 0 | AN4: 0 | AO4: 0 | AP4: 0 | AQ4: 0 | AR4: 0
A5: =ROW(Source!A24) -> 24 | B5: 44887831 | C5: 44887820 | D5: 30531715 | E5: 30515945 | F5: 1 | G5: 30515945 | H5: 3 | I5: 5841000000 | K5: Сборные железобетонные конструкции | L5: 1354 | N5: 1010 | O5: шт. | P5: шт. | Q5: 1 | X5: 100 | Y5: 0 | Z5: 0 | AA5: 0 | AB5: 0 | AC5: 0 | AD5: 0 | AE5: 0 | AG5: 100 | AH5: 3 | AI5: -1 | AK5: 0 | AL5: 0 | AM5: 0 | AN5: 0 | AO5: 0 | AP5: 0 | AQ5: 0 | AR5: 0
A6: =ROW(Source!A27) -> 27 | B6: 44887877 | C6: 44887870 | D6: 30515951 | E6: 30515945 | F6: 1 | G6: 30515945 | H6: 1 | I6: 9999990008 | K6: Трудозатраты рабочих | L6: 1191 | N6: 1013 | O6: чел.-ч. | P6: чел.-ч. | Q6: 1 | X6: 38.9 | Y6: 0 | Z6: 0 | AA6: 0 | AB6: 0 | AC6: 0 | AD6: 1 | AE6: 1 | AG6: 38.9 | AH6: 2 | AI6: 44887877 | AJ6: 7 | AK6: 0 | AL6: 0 | AM6: 0 | AN6: 0 | AO6: 0 | AP6: 0 | AQ6: 0 | AR6: 0
